Workbook
Name Exporta1: #REF!
Name Exporta2: #REF!
Name fibras: #REF!
Name fibras2: #REF!
Name GRAFICO1: #REF!
Name GRAFICO2: #REF!
Name GRAFICO3: #REF!

Sheet A
A2: Matrix properties | Z2: 50kpa | AA2: pf
A3: λ* | B3: 0.0164 | C3: po (kPa) | D3: 300 | Z3: 12.5 | AA3: 101
A4: k | B4: 0.006 | C4: qo (kPa) | D4: 0 | Z4: 25 | AA4: 114
A5: ϕpk | B5: =IF(R58>=AA58,D9,D9-49.3*(R58-AA58)) -> 33.14152 | C5: dq/dp | D5: 3 | Z5: 51 | AA5: 151
A6: Po* (kPa) | B6: =IF(D3>170,D3,170) -> 300 | C6: E or C | D6: C | Z6: 100kpa
A7: vp (1 + ep) | B7: =1+C26 -> 1.613 | C7: pf (kPa) | D7: 650 | Z7: 12.5 | AA7: 183.5
A8: N | B8: =1.83*((1+K49)/K49)^B3+D22 -> 1.8509214 | C8: Pf Estimated | D8: =IF(D5<0,IF((D5*D3-D4)/(D5-B10)<K49/(1+K49)*B6,K49/(1+K49)*B6,(D5*D3-D4)/(D5-B10)),1.4*SQRT(100/D3)*IF((D5*D3-D4)/(D5-B10)<K49/(1+K49)*B6,K49/(1+K49)*B6,(D5*D3-D4)/(D5-B10))) -> 437.46094 | Z8: 25 | AA8: 203
A9: νp | B9: 0.15 | C9: ϕcv | D9: 30.5 | Z9: 51 | AA9: 246
A10: Mpk | B10: =IF(D6="E",6*SIN(B5*PI()/180)/(3+SIN(B5*PI()/180)),6*SIN(B5*PI()/180)/(3-SIN(B5*PI()/180))) -> 1.3370827 | C10: Mcv | D10: =IF(D6="E",6*SIN(D9*PI()/180)/(3+SIN(D9*PI()/180)),6*SIN(D9*PI()/180)/(3-SIN(D9*PI()/180))) -> 1.2217761 | Z10: 200kpa
A11: Fibre Properties | Z11: 12.5 | AA11: 350
A12: Pf (%) | C12: 1 | D12: ψ(n/(1+n)) | E12: =K49/(1+K49) -> 0.5 | Z12: 25 | AA12: 382
A13: ss | C13: 26.57 | D13:  | E13: =LN(0.5)/LN(E12) -> 1 | Z13: 51 | AA13: 438
A14: sf | C14: 9.1 | Z14: 300kpa
A15: s | C15: =1/(C12/100/C14+(1-C12/100)/C13) -> 26.069522 | Z15: 12.5 | AA15: 518.3
A16: sf/s | C16: =C14/C15 -> 0.34906662 | Z16: 25 | AA16: 560
A17: aff | C17: =IF(C22=51,2.1,IF(C22=25,1.4,0.85)) -> 2.1 | Z17: 51 | AA17: 562
A18: Eufibras (MPa) | C18: 910
A19: νf | C19: 0.25
A20: Tensile strength (MPa) | C20: 225
A21: Ve | C21: =((1-C$12/100)/$C$13)/((1-C$12/100)/$C$13+(C12/100)/10) -> 0.97386309
A22: L (mm) | C22: 51 | E22: 0.606 | F22: 0.61170134 | G22: 0.61271862 | H22: 50
E23: 0.61133339 | F23: 0.6112901 | G23: 0.61160394 | H23: 100
E24: 0.613 | F24: 0.60961266 | G24: 0.61086262 | H24: 200
E25: 0.613 | F25: 0.60906073 | G25: 0.60780536 | H25: 300 | Z25: a
A26: e (void ratio after consolidation) | C26: =IF(C22=12.5,IF(D3=52,G22,IF(D3=100,G23,IF(D3=200,G24,G25))),IF(C22=25,IF(D3=50,F22,IF(D3=100,F23,IF(D3=200,F24,F25))),IF(D3=50,E22,IF(D3=100,E23,IF(D3=200,E24,E25))))) -> 0.613 | E26: Pf=1,0% | F26: Pf=1,0% | G26: Pf=1,0%
A27: ad | C27: 6 | E27: L = 51 mm | F27: L = 25 mm | G27: L = 12,5 mm
Y44: =(280/186)^B3 -> 1.0067309
J49: n | K49: 1
J50: ng2 | K50: 1
J51: nx1 | K51: =K49 -> 1
J52: nx2 | K52: =K49 -> 1 | S52: ε
K53: 0
A57: p | B57: q | C57: ffibres | D57: qfibres | E57: Vf | F57: Gp | G57: Gf | H57: εspe | I57: εsfe | J57: qp | K57: po | L57: λ | M57: εvp1 | N57: εvp2 | P57: εvpe | Q57: εvp | R57: v(paste) | S57: v(MSW) | T57: εv | U57: εspp | V57: εs | W57: εa(MSW) | Z57: q/p’ | AA57: vcritico (paste) | AC57: M | AE57: λbarra | AF57: εa | AG57: q | AH57: εv
A58: =D3 -> 300 | B58: =$D$4+(A58-$D$3)*$D$5 -> 0 | C58: 0 | D58: 0 | E58: =(1/$C$16)*($C$12/100)/S58 -> 0.017938773 | F58: =3*(1-2*$B$9)*(A59+A58)/(4*(1+$B$9)*$B$4) -> 45685.462 | G58: =$C$18*$C$17*(A58+100)/100/(2*(1+$C$19))*1000 -> 3057600 | H58: 0 | I58: 0 | J58: 0 | K58: =$B$6 -> 300 | L58: 0 | M58: 0 | N58: 0 | P58: 0 | Q58: =M58+N58 -> 0 | R58: =B7 -> 1.613 | S58: =$C$21*(R58-1)+1 -> 1.5969781 | T58: 0 | U58: 0 | V58: 0 | W58: 0 | X58: =IF(D$6="E",-B58,B58) -> 0 | Y58: =IF(D$6="E",-J58,J58) -> 0 | Z58: =J58/A58 -> 0 | AA58: =B$8/A58^B$3*((1+K$49)/K$49)^-B$3 -> 1.6665805 | AB58: =(R58-AA58) -> -0.05358052 | AC58: =B$10 -> 1.3370827 | AD58: =IF(K58>K57,(1-A58/K58)/((J58+0.01)/A58/$B$10)^(1+K$49)+A58/K58+0.01,(1-A58/K58)/((J58+0.01)/A58/$D$10)^(1+K$49)+A58/K58+0.01) -> 1.01 | AE58: =IF(ABS(-LN(1-(R58-AA58)/R58)/LN(AD58))<1.2*B$3,1.2*SIGN(-LN(1-(R58-AA58)/R58)/LN(AD58))*B$3,-LN(1-(R58-AA58)/R58)/LN(AD58)) -> -3.2841255 | AF58: =W58 -> 0 | AG58: =IF(D$6="E",-B58,IF(D$6="T",-B58,B58)) -> 0 | AH58: =T58 -> 0
A59: =$A58+($D$7-$D$3)/800 -> 300.4375 | B59: =$D$4+(A59-$D$3)*$D$5 -> 1.3125 | C59: =2/PI()*(ATAN((B59/A59)^2))/(1+C$12/C$14*10*(100/A58)^0.5) -> 7.43359e-06 | D59: =3*G58*(I59-I58)+D58 -> 0 | E59: =(1/$C$16)*($C$12/100)/S59 -> 0.017939149 | F59: =3*(1-2*$B$9)*(A60+A59)/(4*(1+$B$9)*$B$4) -> 45785.16 | G59: =$C$18*$C$17*(A59+100)/100/(2*(1+$C$19))*1000 -> 3060944.2 | H59: =(B59-B58)/(3*(1-E58)*F58+3*C58*E58*G58)+H58 -> 9.7512765e-06 | I59: =C58*(H59-H58)+I58 -> 0 | J59: =J58+3*(H59-H58)*F58 -> 1.3364747 | K59: =IF(J59<$B$10*(A58^$K$49*(MAX(K$58)-A58))^(1/(1+$K$49))*($K$49^(1/(1+$K$49))),IF(J59/A59>D$10,IF(MAX(J$58)<0.99*$B$10*(A58^$K$49*(K58-A58))^(1/(1+$K$49))*($K$49^(1/(1+$K$49))),MAX(K$58),((J59/$B$10)^(1+$K$49)/(A59^($K$49)*$K$49))+A59),MAX(K$58)),((J59/$B$10)^(1+$K$49)/(A59^($K$49)*$K$49))+A59) -> 300.44083 | L59: =IF(K59<K58,AE58*(MAX(Z$58)-J58/A58)/(J58/A58/D$10-1)/(1+1*(MAX(Z$58)-J58/A58)/(J58/A58/D$10-1))+B$3-B$4,AE58*(J59/A59/B$10)/(C$27+J59/A59/B$10)) -> -0.0018200196 | M59: =M58+L59*2*(K59-K58)/(K58+K59) -> -2.6724065e-06 | N59: =N58+(B$3-B$4)*2*(K59-K58)/(K58+K59) -> 1.5270729e-05 | P59: =P58+$B$4*2*(A59-A58)/(A59+A58) -> 8.7436244e-06 | Q59: =M59+N59 -> 1.2598323e-05 | R59: =R58-(Q59-Q58+P59-P58)*R58 -> 1.6129656 | S59: =$C$21*(R59-1)+1 -> 1.5969445 | T59: =-(S59-S58)/S58+T58 -> 2.0992655e-05 | U59: =(N59-N58)/(K$49/(1+K$49)*(AC59^(1+K$49)-(J59/A59)^(1+K$49))/(J59/A59)^K$49)*K$50+U58 -> 7.5994931e-08 | V59: =IF(D$6="E",-IF(K58=$B$6,-V58+(H59-H58)*(1-E58)+(I59-I58)*E58,-V58+(H59-H58)*(1-E58)+(I59-I58)*E58+(U59-U58)*(1-E58)),IF(K58=$B$6,V58+(H59-H58)*(1-E58)+(I59-I58)*E58,V58+(H59-H58)*(1-E58)+(I59-I58)*E58+(U59-U58)*(1-E58))) -> 9.5763506e-06 | W59: =T59/3+V59 -> 1.6573902e-05 | X59: =IF(D$6="E",-B59,B59) -> 1.3125 | Y59: =IF(D$6="E",-J59,J59) -> 1.3364747 | Z59: =J59/A59 -> 0.0044484284 | AA59: =B$8/A59^B$3*((1+K$49)/K$49)^-B$3 -> 1.6665407 | AB59: =(R59-AA59) -> -0.053575115 | AC59: =IF(R$58>=AA$58,B$10,IF(K59<K58,(Z59-D$10)*(1+1.25*(D$10-Z59)/MAX(Z$58:Z59)*B$10)+D$10,B$10)) -> 1.3370827 | AD59: =IF(K59>K58,(1-A59/K59)/((J59+0.01)/A59/$B$10)^(1+K$49)+A59/K59+0.01,(1-A59/K59)/((J59+0.01)/A59/$D$10)^(1+K$49)+A59/K59+0.01) -> 1.9951796 | AE59: =IF(ABS(-LN(1-(R59-AA59)/R59)/LN(AD59))<1.2*B$3,1.2*SIGN(-LN(1-(R59-AA59)/R59)/LN(AD59))*B$3,-LN(1-(R59-AA59)/R59)/LN(AD59)) -> -0.047305584 | AF59: =W59 -> 1.6573902e-05 | AG59: =IF(D$6="E",-B59,IF(D$6="T",-B59,B59)) -> 1.3125 | AH59: =T59 -> 2.0992655e-05
A60: =IF(J59/A59<=0.99*$B$10,IF(A59>A58,IF(D$5>0,$A59+($D$7-$D$3)/401,IF(J59/A59>1.01*D$10,A59-($D$7-$D$3)/401,A59)),IF(D$5<0,$A59+($D$7-$D$3)/401,IF(J59/A59>1.01*D$10,A59-($D$7-$D$3)/401,A59))),IF(K59>$B$6,IF(B$10>D$10,IF(J59/A59>1.01*D$10,A59-($D$7-$D$3)/401,A59),A59),IF(MAX(J$58:J59)<0.99*$B$10*(A59^$K$49*(K59-A59))^(1/(1+$K$49))*($K$49^(1/(1+$K$49))),$A59+($D$7-$D$3)/401,IF(J59/A59>1.01*$D$10,$A59-($D$7-$D$3)/401,A59)))) -> 301.31032 | B60: =$D$4+(A60-$D$3)*$D$5 -> 3.9309539 | C60: =2/PI()*(ATAN((B60/A60)^2))/(1+C$12/C$14*10*(100/A59)^0.5) -> 6.6313042e-05 | D60: =3*G59*(I60-I59)+D59 -> 0.0013250488 | E60: =(1/$C$16)*($C$12/100)/S60 -> 0.017940001 | F60: =3*(1-2*$B$9)*(A61+A60)/(4*(1+$B$9)*$B$4) -> 45917.98 | G60: =$C$18*$C$17*(A60+100)/100/(2*(1+$C$19))*1000 -> 3067616.1 | H60: =(B60-B59)/(3*(1-E59)*F59+3*C59*E59*G59)+H59 -> 2.9162665e-05 | I60: =C59*(H60-H59)+I59 -> 1.442963e-10 | J60: =J59+3*(H60-H59)*F59 -> 4.0027353 | K60: =IF(J60<$B$10*(A59^$K$49*(MAX(K$58:K59)-A59))^(1/(1+$K$49))*($K$49^(1/(1+$K$49))),IF(J60/A60>D$10,IF(MAX(J$58:J59)<0.99*$B$10*(A59^$K$49*(K59-A59))^(1/(1+$K$49))*($K$49^(1/(1+$K$49))),MAX(K$58:K59),((J60/$B$10)^(1+$K$49)/(A60^($K$49)*$K$49))+A60),MAX(K$58:K59)),((J60/$B$10)^(1+$K$49)/(A60^($K$49)*$K$49))+A60) -> 301.34006 | L60: =IF(K60<K59,AE59*(MAX(Z$58:Z59)-J59/A59)/(J59/A59/D$10-1)/(1+1*(MAX(Z$58:Z59)-J59/A59)/(J59/A59/D$10-1))+B$3-B$4,AE59*(J60/A60/B$10)/(C$27+J60/A60/B$10)) -> -7.8203678e-05 | M60: =M59+L60*2*(K60-K59)/(K59+K60) -> -2.9061245e-06 | N60: =N59+(B$3-B$4)*2*(K60-K59)/(K59+K60) -> 4.6351969e-05 | P60: =P59+$B$4*2*(A60-A59)/(A60+A59) -> 2.614928e-05 | Q60: =M60+N60 -> 4.3445845e-05 | R60: =R59-(Q60-Q59+P60-P59)*R59 -> 1.6128877 | S60: =$C$21*(R60-1)+1 -> 1.5968688 | T60: =-(S60-S59)/S59+T59 -> 6.8456081e-05 | U60: =(N60-N59)/(K$49/(1+K$49)*(AC60^(1+K$49)-(J60/A60)^(1+K$49))/(J60/A60)^K$49)*K$50+U59 -> 5.3794762e-07 | V60: =IF(D$6="E",-IF(K59=$B$6,-V59+(H60-H59)*(1-E59)+(I60-I59)*E59,-V59+(H60-H59)*(1-E59)+(I60-I59)*E59+(U60-U59)*(1-E59)),IF(K59=$B$6,V59+(H60-H59)*(1-E59)+(I60-I59)*E59,V59+(H60-H59)*(1-E59)+(I60-I59)*E59+(U60-U59)*(1-E59))) -> 2.9093183e-05 | W60: =T60/3+V60 -> 5.1911877e-05 | X60: =IF(D$6="E",-B60,B60) -> 3.9309539 | Y60: =IF(D$6="E",-J60,J60) -> 4.0027353 | Z60: =J60/A60 -> 0.013284428 | AA60: =B$8/A60^B$3*((1+K$49)/K$49)^-B$3 -> 1.6664614 | AB60: =(R60-AA60) -> -0.053573661 | AC60: =IF(R$58>=AA$58,B$10,IF(K60<K59,(Z60-D$10)*(1+1.25*(D$10-Z60)/MAX(Z$58:Z60)*B$10)+D$10,B$10)) -> 1.3370827 | AD60: =IF(K60>K59,(1-A60/K60)/((J60+0.01)/A60/$B$10)^(1+K$49)+A60/K60+0.01,(1-A60/K60)/((J60+0.01)/A60/$D$10)^(1+K$49)+A60/K60+0.01) -> 2.0048252 | AE60: =IF(ABS(-LN(1-(R60-AA60)/R60)/LN(AD60))<1.2*B$3,1.2*SIGN(-LN(1-(R60-AA60)/R60)/LN(AD60))*B$3,-LN(1-(R60-AA60)/R60)/LN(AD60)) -> -0.046978556 | AF60: =W60 -> 5.1911877e-05 | AG60: =IF(D$6="E",-B60,IF(D$6="T",-B60,B60)) -> 3.9309539 | AH60: =T60 -> 6.8456081e-05
A61: =IF(J60/A60<=0.99*$B$10,IF(A60>A59,IF(D$5>0,$A60+($D$7-$D$3)/401,IF(J60/A60>1.01*D$10,A60-($D$7-$D$3)/401,A60)),IF(D$5<0,$A60+($D$7-$D$3)/401,IF(J60/A60>1.01*D$10,A60-($D$7-$D$3)/401,A60))),IF(K60>$B$6,IF(B$10>D$10,IF(J60/A60>1.01*D$10,A60-($D$7-$D$3)/401,A60),A60),IF(MAX(J$58:J60)<0.99*$B$10*(A60^$K$49*(K60-A60))^(1/(1+$K$49))*($K$49^(1/(1+$K$49))),$A60+($D$7-$D$3)/401,IF(J60/A60>1.01*$D$10,$A60-($D$7-$D$3)/401,A60)))) -> 302.18314 | B61: =$D$4+(A61-$D$3)*$D$5 -> 6.5494077 | C61: =2/PI()*(ATAN((B61/A61)^2))/(1+C$12/C$14*10*(100/A60)^0.5) -> 0.00018312134 | D61: =3*G60*(I61-I60)+D60 -> 0.01313611 | E61: =(1/$C$16)*($C$12/100)/S61 -> 0.017940863 | F61: =3*(1-2*$B$9)*(A62+A61)/(4*(1+$B$9)*$B$4) -> 46050.8 | G61: =$C$18*$C$17*(A61+100)/100/(2*(1+$C$19))*1000 -> 3074287.9 | H61: =(B61-B60)/(3*(1-E60)*F60+3*C60*E60*G60)+H60 -> 4.8516531e-05 | I61: =C60*(H61-H60)+I60 -> 1.42771e-09 | J61: =J60+3*(H61-H60)*F60 -> 6.6688066 | K61: =IF(J61<$B$10*(A60^$K$49*(MAX(K$58:K60)-A60))^(1/(1+$K$49))*($K$49^(1/(1+$K$49))),IF(J61/A61>D$10,IF(MAX(J$58:J60)<0.99*$B$10*(A60^$K$49*(K60-A60))^(1/(1+$K$49))*($K$49^(1/(1+$K$49))),MAX(K$58:K60),((J61/$B$10)^(1+$K$49)/(A61^($K$49)*$K$49))+A61),MAX(K$58:K60)),((J61/$B$10)^(1+$K$49)/(A61^($K$49)*$K$49))+A61) -> 302.26546 | L61: =IF(K61<K60,AE60*(MAX(Z$58:Z60)-J60/A60)/(J60/A60/D$10-1)/(1+1*(MAX(Z$58:Z60)-J60/A60)/(J60/A60/D$10-1))+B$3-B$4,AE60*(J61/A61/B$10)/(C$27+J61/A61/B$10)) -> -0.00012887687 | M61: =M60+L61*2*(K61-K60)/(K60+K61) -> -3.3012902e-06 | N61: =N60+(B$3-B$4)*2*(K61-K60)/(K60+K61) -> 7.8240733e-05 | P61: =P60+$B$4*2*(A61-A60)/(A61+A60) -> 4.3504589e-05 | Q61: =M61+N61 -> 7.4939443e-05 | R61: =R60-(Q61-Q60+P61-P60)*R60 -> 1.612809 | S61: =$C$21*(R61-1)+1 -> 1.596792 | T61: =-(S61-S60)/S60+T60 -> 0.00011650545 | U61: =(N61-N60)/(K$49/(1+K$49)*(AC61^(1+K$49)-(J61/A61)^(1+K$49))/(J61/A61)^K$49)*K$50+U60 -> 1.3254417e-06 | V61: =IF(D$6="E",-IF(K60=$B$6,-V60+(H61-H60)*(1-E60)+(I61-I60)*E60,-V60+(H61-H60)*(1-E60)+(I61-I60)*E60+(U61-U60)*(1-E60)),IF(K60=$B$6,V60+(H61-H60)*(1-E60)+(I61-I60)*E60,V60+(H61-H60)*(1-E60)+(I61-I60)*E60+(U61-U60)*(1-E60))) -> 4.887323e-05 | W61: =T61/3+V61 -> 8.770838e-05 | X61: =IF(D$6="E",-B61,B61) -> 6.5494077 | Y61: =IF(D$6="E",-J61,J61) -> 6.6688066 | Z61: =J61/A61 -> 0.022068758 | AA61: =B$8/A61^B$3*((1+K$49)/K$49)^-B$3 -> 1.6663824 | AB61: =(R61-AA61) -> -0.053573397 | AC61: =IF(R$58>=AA$58,B$10,IF(K61<K60,(Z61-D$10)*(1+1.25*(D$10-Z61)/MAX(Z$58:Z61)*B$10)+D$10,B$10)) -> 1.3370827 | AD61: =IF(K61>K60,(1-A61/K61)/((J61+0.01)/A61/$B$10)^(1+K$49)+A61/K61+0.01,(1-A61/K61)/((J61+0.01)/A61/$D$10)^(1+K$49)+A61/K61+0.01) -> 2.0064638 | AE61: =IF(ABS(-LN(1-(R61-AA61)/R61)/LN(AD61))<1.2*B$3,1.2*SIGN(-LN(1-(R61-AA61)/R61)/LN(AD61))*B$3,-LN(1-(R61-AA61)/R61)/LN(AD61)) -> -0.046925467 | AF61: =W61 -> 8.770838e-05 | AG61: =IF(D$6="E",-B61,IF(D$6="T",-B61,B61)) -> 6.5494077 | AH61: =T61 -> 0.00011650545
A62: =IF(J61/A61<=0.99*$B$10,IF(A61>A60,IF(D$5>0,$A61+($D$7-$D$3)/401,IF(J61/A61>1.01*D$10,A61-($D$7-$D$3)/401,A61)),IF(D$5<0,$A61+($D$7-$D$3)/401,IF(J61/A61>1.01*D$10,A61-($D$7-$D$3)/401,A61))),IF(K61>$B$6,IF(B$10>D$10,IF(J61/A61>1.01*D$10,A61-($D$7-$D$3)/401,A61),A61),IF(MAX(J$58:J61)<0.99*$B$10*(A61^$K$49*(K61-A61))^(1/(1+$K$49))*($K$49^(1/(1+$K$49))),$A61+($D$7-$D$3)/401,IF(J61/A61>1.01*$D$10,$A61-($D$7-$D$3)/401,A61)))) -> 303.05595 | B62: =$D$4+(A62-$D$3)*$D$5 -> 9.1678616 | C62: =2/PI()*(ATAN((B62/A62)^2))/(1+C$12/C$14*10*(100/A61)^0.5) -> 0.0003569514 | D62: =3*G61*(I62-I61)+D61 -> 0.045724028 | E62: =(1/$C$16)*($C$12/100)/S62 -> 0.017941735 | F62: =3*(1-2*$B$9)*(A63+A62)/(4*(1+$B$9)*$B$4) -> 46183.62 | G62: =$C$18*$C$17*(A62+100)/100/(2*(1+$C$19))*1000 -> 3080959.7 | H62: =(B62-B61)/(3*(1-E61)*F61+3*C61*E61*G61)+H61 -> 6.7811845e-05 | I62: =C61*(H62-H61)+I61 -> 4.9610938e-09 | J62: =J61+3*(H62-H61)*F61 -> 9.3345006 | K62: =IF(J62<$B$10*(A61^$K$49*(MAX(K$58:K61)-A61))^(1/(1+$K$49))*($K$49^(1/(1+$K$49))),IF(J62/A62>D$10,IF(MAX(J$58:J61)<0.99*$B$10*(A61^$K$49*(K61-A61))^(1/(1+$K$49))*($K$49^(1/(1+$K$49))),MAX(K$58:K61),((J62/$B$10)^(1+$K$49)/(A62^($K$49)*$K$49))+A62),MAX(K$58:K61)),((J62/$B$10)^(1+$K$49)/(A62^($K$49)*$K$49))+A62) -> 303.21677 | L62: =IF(K62<K61,AE61*(MAX(Z$58:Z61)-J61/A61)/(J61/A61/D$10-1)/(1+1*(MAX(Z$58:Z61)-J61/A61)/(J61/A61/D$10-1))+B$3-B$4,AE61*(J62/A62/B$10)/(C$27+J62/A62/B$10)) -> -0.00017947465 | M62: =M61+L62*2*(K62-K61)/(K61+K62) -> -3.8652622e-06 | N62: =N61+(B$3-B$4)*2*(K62-K61)/(K61+K62) -> 0.00011092116 | P62: =P61+$B$4*2*(A62-A61)/(A62+A61) -> 6.0809842e-05 | Q62: =M62+N62 -> 0.0001070559 | R62: =R61-(Q62-Q61+P62-P61)*R61 -> 1.6127292 | S62: =$C$21*(R62-1)+1 -> 1.5967144 | T62: =-(S62-S61)/S61+T61 -> 0.0001651182 | U62: =(N62-N61)/(K$49/(1+K$49)*(AC62^(1+K$49)-(J62/A62)^(1+K$49))/(J62/A62)^K$49)*K$50+U61 -> 2.4521201e-06 | V62: =IF(D$6="E",-IF(K61=$B$6,-V61+(H62-H61)*(1-E61)+(I62-I61)*E61,-V61+(H62-H61)*(1-E61)+(I62-I61)*E61+(U62-U61)*(1-E61)),IF(K61=$B$6,V61+(H62-H61)*(1-E61)+(I62-I61)*E61,V61+(H62-H61)*(1-E61)+(I62-I61)*E61+(U62-U61)*(1-E61))) -> 6.8928899e-05 | W62: =T62/3+V62 -> 0.0001239683 | X62: =IF(D$6="E",-B62,B62) -> 9.1678616 | Y62: =IF(D$6="E",-J62,J62) -> 9.3345006 | Z62: =J62/A62 -> 0.030801245 | AA62: =B$8/A62^B$3*((1+K$49)/K$49)^-B$3 -> 1.6663035 | AB62: =(R62-AA62) -> -0.053574285 | AC62: =IF(R$58>=AA$58,B$10,IF(K62<K61,(Z62-D$10)*(1+1.25*(D$10-Z62)/MAX(Z$58:Z62)*B$10)+D$10,B$10)) -> 1.3370827 | AD62: =IF(K62>K61,(1-A62/K62)/((J62+0.01)/A62/$B$10)^(1+K$49)+A62/K62+0.01,(1-A62/K62)/((J62+0.01)/A62/$D$10)^(1+K$49)+A62/K62+0.01) -> 2.0068012 | AE62: =IF(ABS(-LN(1-(R62-AA62)/R62)/LN(AD62))<1.2*B$3,1.2*SIGN(-LN(1-(R62-AA62)/R62)/LN(AD62))*B$3,-LN(1-(R62-AA62)/R62)/LN(AD62)) -> -0.046917185 | AF62: =W62 -> 0.0001239683 | AG62: =IF(D$6="E",-B62,IF(D$6="T",-B62,B62)) -> 9.1678616 | AH62: =T62 -> 0.0001651182
A63: =IF(J62/A62<=0.99*$B$10,IF(A62>A61,IF(D$5>0,$A62+($D$7-$D$3)/401,IF(J62/A62>1.01*D$10,A62-($D$7-$D$3)/401,A62)),IF(D$5<0,$A62+($D$7-$D$3)/401,IF(J62/A62>1.01*D$10,A62-($D$7-$D$3)/401,A62))),IF(K62>$B$6,IF(B$10>D$10,IF(J62/A62>1.01*D$10,A62-($D$7-$D$3)/401,A62),A62),IF(MAX(J$58:J62)<0.99*$B$10*(A62^$K$49*(K62-A62))^(1/(1+$K$49))*($K$49^(1/(1+$K$49))),$A62+($D$7-$D$3)/401,IF(J62/A62>1.01*$D$10,$A62-($D$7-$D$3)/401,A62)))) -> 303.92877 | B63: =$D$4+(A63-$D$3)*$D$5 -> 11.786315 | C63: =2/PI()*(ATAN((B63/A63)^2))/(1+C$12/C$14*10*(100/A62)^0.5) -> 0.00058691254 | D63: =3*G62*(I63-I62)+D62 -> 0.1091878 | E63: =(1/$C$16)*($C$12/100)/S63 -> 0.017942617 | F63: =3*(1-2*$B$9)*(A64+A63)/(4*(1+$B$9)*$B$4) -> 46316.441 | G63: =$C$18*$C$17*(A63+100)/100/(2*(1+$C$19))*1000 -> 3087631.5 | H63: =(B63-B62)/(3*(1-E62)*F62+3*C62*E62*G62)+H62 -> 8.7047614e-05 | I63: =C62*(H63-H62)+I62 -> 1.1827328e-08 | J63: =J62+3*(H63-H62)*F62 -> 11.999633 | K63: =IF(J63<$B$10*(A62^$K$49*(MAX(K$58:K62)-A62))^(1/(1+$K$49))*($K$49^(1/(1+$K$49))),IF(J63/A63>D$10,IF(MAX(J$58:J62)<0.99*$B$10*(A62^$K$49*(K62-A62))^(1/(1+$K$49))*($K$49^(1/(1+$K$49))),MAX(K$58:K62),((J63/$B$10)^(1+$K$49)/(A63^($K$49)*$K$49))+A63),MAX(K$58:K62)),((J63/$B$10)^(1+$K$49)/(A63^($K$49)*$K$49))+A63) -> 304.19377 | L63: =IF(K63<K62,AE62*(MAX(Z$58:Z62)-J62/A62)/(J62/A62/D$10-1)/(1+1*(MAX(Z$58:Z62)-J62/A62)/(J62/A62/D$10-1))+B$3-B$4,AE62*(J63/A63/B$10)/(C$27+J63/A63/B$10)) -> -0.00022976638 | M63: =M62+L63*2*(K63-K62)/(K62+K63) -> -4.604404e-06 | N63: =N62+(B$3-B$4)*2*(K63-K62)/(K62+K63) -> 0.00014437721 | P63: =P62+$B$4*2*(A63-A62)/(A63+A62) -> 7.8065327e-05 | Q63: =M63+N63 -> 0.00013977281 | R63: =R62-(Q63-Q62+P63-P62)*R62 -> 1.6126487 | S63: =$C$21*(R63-1)+1 -> 1.5966359 | T63: =-(S63-S62)/S62+T62 -> 0.00021427259 | U63: =(N63-N62)/(K$49/(1+K$49)*(AC63^(1+K$49)-(J63/A63)^(1+K$49))/(J63/A63)^K$49)*K$50+U62 -> 3.9311027e-06 | V63: =IF(D$6="E",-IF(K62=$B$6,-V62+(H63-H62)*(1-E62)+(I63-I62)*E62,-V62+(H63-H62)*(1-E62)+(I63-I62)*E62+(U63-U62)*(1-E62)),IF(K62=$B$6,V62+(H63-H62)*(1-E62)+(I63-I62)*E62,V62+(H63-H62)*(1-E62)+(I63-I62)*E62+(U63-U62)*(1-E62))) -> 8.9272114e-05 | W63: =T63/3+V63 -> 0.00016069631 | X63: =IF(D$6="E",-B63,B63) -> 11.786315 | Y63: =IF(D$6="E",-J63,J63) -> 11.999633 | Z63: =J63/A63 -> 0.039481727 | AA63: =B$8/A63^B$3*((1+K$49)/K$49)^-B$3 -> 1.6662249 | AB63: =(R63-AA63) -> -0.053576288 | AC63: =IF(R$58>=AA$58,B$10,IF(K63<K62,(Z63-D$10)*(1+1.25*(D$10-Z63)/MAX(Z$58:Z63)*B$10)+D$10,B$10)) -> 1.3370827 | AD63: =IF(K63>K62,(1-A63/K63)/((J63+0.01)/A63/$B$10)^(1+K$49)+A63/K63+0.01,(1-A63/K63)/((J63+0.01)/A63/$D$10)^(1+K$49)+A63/K63+0.01) -> 2.0065945 | AE63: =IF(ABS(-LN(1-(R63-AA63)/R63)/LN(AD63))<1.2*B$3,1.2*SIGN(-LN(1-(R63-AA63)/R63)/LN(AD63))*B$3,-LN(1-(R63-AA63)/R63)/LN(AD63)) -> -0.046928158 | AF63: =W63 -> 0.00016069631 | AG63: =IF(D$6="E",-B63,IF(D$6="T",-B63,B63)) -> 11.786315 | AH63: =T63 -> 0.00021427259
A64: =IF(J63/A63<=0.99*$B$10,IF(A63>A62,IF(D$5>0,$A63+($D$7-$D$3)/401,IF(J63/A63>1.01*D$10,A63-($D$7-$D$3)/401,A63)),IF(D$5<0,$A63+($D$7-$D$3)/401,IF(J63/A63>1.01*D$10,A63-($D$7-$D$3)/401,A63))),IF(K63>$B$6,IF(B$10>D$10,IF(J63/A63>1.01*D$10,A63-($D$7-$D$3)/401,A63),A63),IF(MAX(J$58:J63)<0.99*$B$10*(A63^$K$49*(K63-A63))^(1/(1+$K$49))*($K$49^(1/(1+$K$49))),$A63+($D$7-$D$3)/401,IF(J63/A63>1.01*$D$10,$A63-($D$7-$D$3)/401,A63)))) -> 304.80159 | B64: =$D$4+(A64-$D$3)*$D$5 -> 14.404769 | C64: =2/PI()*(ATAN((B64/A64)^2))/(1+C$12/C$14*10*(100/A63)^0.5) -> 0.00087212797 | D64: =3*G63*(I64-I63)+D63 -> 0.21343428 | E64: =(1/$C$16)*($C$12/100)/S64 -> 0.017943508 | F64: =3*(1-2*$B$9)*(A65+A64)/(4*(1+$B$9)*$B$4) -> 46449.261 | G64: =$C$18*$C$17*(A64+100)/100/(2*(1+$C$19))*1000 -> 3094303.4 | H64: =(B64-B63)/(3*(1-E63)*F63+3*C63*E63*G63)+H63 -> 0.00010622288 | I64: =C63*(H64-H63)+I63 -> 2.308153e-08 | J64: =J63+3*(H64-H63)*F63 -> 14.664022 | K64: =IF(J64<$B$10*(A63^$K$49*(MAX(K$58:K63)-A63))^(1/(1+$K$49))*($K$49^(1/(1+$K$49))),IF(J64/A64>D$10,IF(MAX(J$58:J63)<0.99*$B$10*(A63^$K$49*(K63-A63))^(1/(1+$K$49))*($K$49^(1/(1+$K$49))),MAX(K$58:K63),((J64/$B$10)^(1+$K$49)/(A64^($K$49)*$K$49))+A64),MAX(K$58:K63)),((J64/$B$10)^(1+$K$49)/(A64^($K$49)*$K$49))+A64) -> 305.1962 | L64: =IF(K64<K63,AE63*(MAX(Z$58:Z63)-J63/A63)/(J63/A63/D$10-1)/(1+1*(MAX(Z$58:Z63)-J63/A63)/(J63/A63/D$10-1))+B$3-B$4,AE63*(J64/A64/B$10)/(C$27+J64/A64/B$10)) -> -0.00027974557 | M64: =M63+L64*2*(K64-K63)/(K63+K64) -> -5.5247526e-06 | N64: =N63+(B$3-B$4)*2*(K64-K63)/(K63+K64) -> 0.00017859268 | P64: =P63+$B$4*2*(A64-A63)/(A64+A63) -> 9.5271328e-05 | Q64: =M64+N64 -> 0.00017306792 | R64: =R63-(Q64-Q63+P64-P63)*R63 -> 1.6125672 | S64: =$C$21*(R64-1)+1 -> 1.5965566 | T64: =-(S64-S63)/S63+T63 -> 0.00026394701 | U64: =(N64-N63)/(K$49/(1+K$49)*(AC64^(1+K$49)-(J64/A64)^(1+K$49))/(J64/A64)^K$49)*K$50+U63 -> 5.7749902e-06 | V64: =IF(D$6="E",-IF(K63=$B$6,-V63+(H64-H63)*(1-E63)+(I64-I63)*E63,-V63+(H64-H63)*(1-E63)+(I64-I63)*E63+(U64-U63)*(1-E63)),IF(K63=$B$6,V63+(H64-H63)*(1-E63)+(I64-I63)*E63,V63+(H64-H63)*(1-E63)+(I64-I63)*E63+(U64-U63)*(1-E63))) -> 0.00010991433 | W64: =T64/3+V64 -> 0.00019789666 | X64: =IF(D$6="E",-B64,B64) -> 14.404769 | Y64: =IF(D$6="E",-J64,J64) -> 14.664022 | Z64: =J64/A64 -> 0.048110059 | AA64: =B$8/A64^B$3*((1+K$49)/K$49)^-B$3 -> 1.6661466 | AB64: =(R64-AA64) -> -0.053579368 | AC64: =IF(R$58>=AA$58,B$10,IF(K64<K63,(Z64-D$10)*(1+1.25*(D$10-Z64)/MAX(Z$58:Z64)*B$10)+D$10,B$10)) -> 1.3370827 | AD64: =IF(K64>K63,(1-A64/K64)/((J64+0.01)/A64/$B$10)^(1+K$49)+A64/K64+0.01,(1-A64/K64)/((J64+0.01)/A64/$D$10)^(1+K$49)+A64/K64+0.01) -> 2.0060533 | AE64: =IF(ABS(-LN(1-(R64-AA64)/R64)/LN(AD64))<1.2*B$3,1.2*SIGN(-LN(1-(R64-AA64)/R64)/LN(AD64))*B$3,-LN(1-(R64-AA64)/R64)/LN(AD64)) -> -0.046951329 | AF64: =W64 -> 0.00019789666 | AG64: =IF(D$6="E",-B64,IF(D$6="T",-B64,B64)) -> 14.404769 | AH64: =T64 -> 0.00026394701
...

Sheet Graficos_resumo

Sheet Exp_res
A1: 50 KPA | B1: 0.01 | C1: L12,5 | E1: 50 KPA | F1: 0.01 | G1: L25 | I1: 50 KPA | J1: 0.01 | K1: L51 | M1: 100 KPA | N1: 0.01 | O1: L12,5 | Q1: 100 KPA | R1: 0.01 | S1: L25 | U1: 100 KPA | V1: 0.01 | W1: L51 | Y1: 200 KPA | Z1: 0.01 | AA1: L12,5 | AC1: 200 KPA | AD1: 0.01 | AE1: L25 | AG1: 200 KPA | AH1: 0.01 | AI1: L51 | AK1: 300 KPA | AL1: 0.01 | AM1: L12,5 | AO1: 300 KPA | AP1: 0.01 | AQ1: L25 | AS1: 300 KPA | AT1: 0.01 | AU1: L51 | AW1: L12,5 | AZ1: L25 | BC1: L50 | BF1: L12,5 | BI1: L25 | BL1: L50 | BO1: L12,5 | BR1: L25 | BU1: L50 | BX1: L12,5 | CA1: L25 | CD1: L50
A2: def. axial | B2: P.desv. | C2: def vol | E2: def. axial | F2: P.desv. | G2: def vol | I2: def. axial | J2: P.desv. | K2: def vol | M2: def. axial | N2: P.desv. | O2: def vol | Q2: def. axial | R2: P.desv. | S2: def vol | U2: def. axial | V2: P.desv. | W2: def vol | Y2: def. axial | Z2: P.desv. | AA2: def vol | AC2: def. axial | AD2: P.desv. | AE2: def vol | AG2: def. axial | AH2: P.desv. | AI2: def vol | AK2: def. axial | AL2: P.desv. | AM2: def vol | AO2: def. axial | AP2: P.desv. | AQ2: def vol | AS2: def. axial | AT2: P.desv. | AU2: def vol | AW2: σ3 = 50 kPa, dq/dp=3, Pf=1.0% | AZ2: σ3 = 50 kPa, dq/dp=3, Pf=1.0% | BC2: σ3 = 50 kPa, dq/dp=3, Pf=1.0% | BF2: σ3 = 100 kPa, dq/dp=3, Pf=1.0% | BI2: σ3 = 100 kPa, dq/dp=3, Pf=1.0% | BL2: σ3 = 100 kPa, dq/dp=3, Pf=1.0% | BO2: σ3 = 200 kPa, dq/dp=3, Pf=1.0% | BR2: σ3 = 200 kPa, dq/dp=3, Pf=1.0% | BU2: σ3 = 200 kPa, dq/dp=3, Pf=1.0% | BX2: σ3 = 300 kPa, dq/dp=3, Pf=1.0% | CA2: σ3 = 300 kPa, dq/dp=3, Pf=1.0% | CD2: σ3 = 300 kPa, dq/dp=3, Pf=1.0%
A3: 0 | B3: 0 | C3: 0 | E3: 0 | F3: 0 | G3: 0 | I3: 0 | J3: 0 | K3: 0 | M3: 0 | N3: 0 | O3: 0 | Q3: 0 | R3: 0 | S3: 0 | U3: 0 | V3: 0 | W3: 0 | Y3: 0 | Z3: 0 | AA3: 0 | AC3: 0 | AD3: 0 | AE3: 0 | AG3: 0 | AH3: 0 | AI3: 0 | AK3: 0 | AL3: 0 | AM3: 0 | AO3: 0 | AP3: 0 | AQ3: 0 | AS3: 0 | AT3: 0 | AU3: 0 | AW3: 0 | AX3: 0 | AY3: 0 | AZ3: 0 | BA3: 0 | BB3: 0 | BC3: 0 | BD3: 0 | BE3: 0 | BF3: 0 | BG3: 0 | BH3: 0 | BI3: 0 | BJ3: 0 | BK3: 0 | BL3: 0 | BM3: 0 | BN3: 0 | BO3: 0 | BP3: 0 | BQ3: 0 | BR3: 0 | BS3: 0 | BT3: 0 | BU3: 0 | BV3: 0 | BW3: 0 | BX3: 0 | BY3: 0 | BZ3: 0 | CA3: 0 | CB3: 0 | CC3: 0 | CD3: 0 | CE3: 0 | CF3: 0
A4: 0.0015092299 | B4: 54.980893 | C4: 0 | E4: 0.0010064211 | F4: 31.565303 | G4: -0.0001142837 | I4: 0.00050301811 | J4: 16.792407 | K4: -5.3677786e-05 | M4: 0.0010063266 | N4: 67.020514 | O4: 0.00022846001 | Q4: 0.0015097465 | R4: 74.384743 | S4: 0.0014391777 | U4: 0.0015096047 | V4: 52.417873 | W4: 6.0497721e-05 | Y4: 0.0010065585 | Z4: 69.034383 | AA4: 0.0013790682 | AC4: 0.0020134234 | AD4: 134.93961 | AE4: 0.00086173247 | AG4: 0.0025188707 | AH4: 127.16425 | AI4: 0.0010410907 | AK4: 0 | AL4: 7.01 | AM4: 0 | AO4: 0.0010069821 | AP4: 116.76618 | AQ4: 0.00028987756 | AS4: 0.0010073881 | AT4: 68.80487 | AU4: -6.0794549e-05 | AW4: 1.1945666e-05 | AX4: 0.21 | AY4: 8.2563053e-06 | AZ4: 1.5675404e-05 | BA4: 0.275625 | BB4: 1.0834462e-05 | BC4: 2.6641358e-05 | BD4: 0.46875 | BE4: 1.8413043e-05 | BF4: 9.8138249e-06 | BG4: 0.345 | BH4: 6.7830748e-06 | BI4: 1.226551e-05 | BJ4: 0.43125 | BK4: 8.4775985e-06 | BL4: 1.7060264e-05 | BM4: 0.6 | BN4: 1.1791611e-05 | BO4: 1.1458587e-05 | BP4: 0.6 | BQ4: 1.4671326e-05 | BR4: 1.3821135e-05 | BS4: 0.73125 | BT4: 1.7451252e-05 | BU4: 1.7507637e-05 | BV4: 0.9375 | BW4: 2.1743386e-05 | BX4: 1.0817828e-05 | BY4: 0.84375 | BZ4: 1.3980002e-05 | CA4: 1.2900321e-05 | CB4: 1.0125 | CC4: 1.653486e-05 | CD4: 1.6573902e-05 | CE4: 1.3125 | CF4: 2.0992655e-05
A5: 0.0025153831 | B5: 71.929073 | C5: -0.00023497693 | E5: 0.0030192634 | F5: 67.258944 | G5: 0.00063192166 | I5: 0.0055331992 | J5: 120.38021 | K5: 0.0013218155 | M5: 0.0015094898 | N5: 95.933774 | O5: 0.00028893472 | Q5: 0.0050324885 | R5: 166.30839 | S5: 0.0016745572 | U5: 0.0030192093 | V5: 110.1788 | W5: 0.00074613856 | Y5: 0.004026234 | Z5: 225.68943 | AA5: 0.0018432424 | AC5: 0.0055369143 | AD5: 328.63885 | AE5: 0.0016090161 | AG5: 0.007052838 | AH5: 295.71655 | AI5: 0.0018658508 | AK5: 0.00050344261 | AL5: 32.358593 | AM5: 0 | AO5: 0.0030209464 | AP5: 320.8125 | AQ5: 0.0011595102 | AS5: 0.0030221642 | AT5: 170.94267 | AU5: 0.00074979944 | AW5: 3.5727506e-05 | AX5: 0.62895262 | AY5: 2.4693299e-05 | AZ5: 4.6861963e-05 | BA5: 0.82550031 | BB5: 3.2390087e-05 | BC5: 7.9541592e-05 | BD5: 1.4039121 | BE5: 5.4976442e-05 | BF5: 2.9358848e-05 | BG5: 1.0332793 | BH5: 2.0292141e-05 | BI5: 3.6682703e-05 | BJ5: 1.2915991 | BK5: 2.5354207e-05 | BL5: 5.0993657e-05 | BM5: 1.7970075 | BN5: 3.5245841e-05 | BO5: 3.5542336e-05 | BP5: 1.7970075 | BQ5: 4.7062133e-05 | BR5: 4.3236342e-05 | BS5: 2.1901029 | BT5: 5.6976445e-05 | BU5: 5.5367086e-05 | BV5: 2.8078242 | BW5: 7.2551525e-05 | BX5: 3.3393609e-05 | BY5: 2.5270418 | BZ5: 4.4355607e-05 | CA5: 4.0049552e-05 | CB5: 3.0324501 | CC5: 5.3039914e-05 | CD5: 5.1911877e-05 | CE5: 3.9309539 | CF5: 6.8456081e-05
A6: 0.0055338428 | B6: 124.92797 | C6: 0.00051694925 | E6: 0.0060385268 | F6: 126.19761 | G6: 0.0014386302 | I6: 0.012072435 | J6: 178.0862 | K6: 0 | M6: 0.0040253062 | N6: 172.77338 | O6: 0.0010952642 | Q6: 0.0085552304 | R6: 230.36295 | S6: 0.0018426854 | U6: 0.0070448218 | V6: 194.95903 | W6: 0.0012704521 | Y6: 0.008052468 | Z6: 367.79027 | AA6: 0.0026505018 | AC6: 0.0090604052 | AD6: 464.58123 | AE6: 0.0021341343 | AG6: 0.010579257 | AH6: 411.47144 | AI6: 0.0026365284 | AK6: 0.002517213 | AL6: 233.83982 | AM6: 0.00080857109 | AO6: 0.0055384018 | AP6: 482.88321 | AQ6: 0.0019077988 | AS6: 0.0060443285 | AT6: 277.20562 | AU6: 0.0015603934 | AW6: 5.9442597e-05 | AX6: 1.0479052 | AY6: 4.1084634e-05 | AZ6: 7.7932447e-05 | BA6: 1.3753756 | BB6: 5.3867259e-05 | BC6: 0.00013209724 | BD6: 2.3390742 | BE6: 9.1314676e-05 | BF6: 4.8858925e-05 | BG6: 1.7215586 | BH6: 3.3770352e-05 | BI6: 6.1029266e-05 | BJ6: 2.1519483 | BK6: 4.2182688e-05 | BL6: 8.4788679e-05 | BM6: 2.994015 | BN6: 5.8607221e-05 | BO6: 5.9823025e-05 | BP6: 2.994015 | BQ6: 7.9701266e-05 | BR6: 7.2942384e-05 | BS6: 3.6489557 | BT6: 9.6861957e-05 | BU6: 9.3717221e-05 | BV6: 4.6781484 | BW6: 0.00012396228 | BX6: 5.6151316e-05 | BY6: 4.2103335 | BZ6: 7.4966943e-05 | CA6: 6.7463559e-05 | CB6: 5.0524002 | CC6: 8.9885654e-05 | CD6: 8.770838e-05 | CE6: 6.5494077 | CF6: 0.00011650545
A7: 0.012073839 | B7: 144.23863 | C7: -0.0018395337 | E7: 0.015096317 | F7: 179.75548 | G7: -0.001095779 | I7: 0.01861167 | J7: 216.04673 | K7: -0.0018384642 | M7: 0.0095601023 | N7: 250.82897 | O7: 0.00045692003 | Q7: 0.013587719 | R7: 274.74049 | S7: 0.00040350776 | U7: 0.012580039 | V7: 289.55231 | W7: 0.001095681 | Y7: 0.011072144 | Z7: 430.82996 | AA7: 0.0026505018 | AC7: 0.013087252 | AD7: 538.91925 | AE7: 0.0018446461 | AG7: 0.017128321 | AH7: 556.19077 | AI7: 0.0025283631 | AK7: 0.0050344261 | AL7: 421.34575 | AM7: 0.0015564993 | AO7: 0.0085593482 | AP7: 607.57925 | AQ7: 0.0020830736 | AS7: 0.0095701867 | AT7: 453.82307 | AU7: 0.0019656904 | AW7: 8.309063e-05 | AX7: 1.4668579 | AY7: 5.7430564e-05 | AZ7: 0.00010888519 | BA7: 1.9252509 | BB7: 7.5266549e-05 | BC7: 0.00018429464 | BD7: 3.2742363 | BE7: 0.0001274305 | BF7: 6.8313954e-05 | BG7: 2.4098379 | BH7: 4.721785e-05 | BI7: 8.530462e-05 | BJ7: 3.0122974 | BK7: 5.8963315e-05 | BL7: 0.0001184425 | BM7: 4.1910224 | BN7: 8.1876482e-05 | BO7: 8.4301897e-05 | BP7: 4.1910224 | BQ7: 0.00011258057 | BR7: 0.00010294134 | BS7: 5.1078086 | BT7: 0.00013709362 | BU7: 0.00013256235 | BV7: 6.5484726 | BW7: 0.00017594706 | BX7: 7.9092298e-05 | BY7: 5.8936253 | BZ7: 0.00010580761 | CA7: 9.5144616e-05 | CB7: 7.0723504 | CC7: 0.00012706137 | CD7: 0.0001239683 | CE7: 9.1678616 | CF7: 0.0001651182
A8: 0.021129218 | B8: 171.97836 | C8: -0.0062101046 | E8: 0.023147686 | F8: 193.933 | G8: -0.0039730394 | I8: 0.028169014 | J8: 259.50496 | K8: -0.0062064941 | M8: 0.017107552 | N8: 271.47028 | O8: -0.0025332184 | Q8: 0.019626705 | R8: 346.37417 | S8: -0.0029388815 | U8: 0.02264407 | V8: 367.92932 | W8: -0.00063186509 | Y8: 0.016608215 | Z8: 496.27808 | AA8: 0.0015001571 | AC8: 0.01812081 | AD8: 604.75882 | AE8: 0.00063283479 | AG8: 0.027203804 | AH8: 665.06787 | AI8: 0.00027041316 | AK8: 0.0080550817 | AL8: 552.43087 | AM8: 0.0019607849 | AO8: 0.011076804 | AP8: 701.71653 | AQ8: 0.0021370043 | AS8: 0.013599739 | AT8: 598.98102 | AU8: 0.0023709874 | AW8: 0.00010667131 | AX8: 1.8858105 | AY8: 7.373134e-05 | AZ8: 0.00013971863 | BA8: 2.4751262 | BB8: 9.6588519e-05 | BC8: 0.00023612126 | BD8: 4.2093984 | BE8: 0.00016332663 | BF8: 8.7723842e-05 | BG8: 3.0981172 | BH8: 6.0634773e-05 | BI8: 0.00010950821 | BJ8: 3.8726465 | BK8: 7.5696359e-05 | BL8: 0.00015195245 | BM8: 5.3880299 | BN8: 0.00010505435 | BO8: 0.00010898042 | BP8: 5.3880299 | BQ8: 0.00014569285 | BR8: 0.00013323551 | BS8: 6.5666615 | BT8: 0.0001776585 | BU8: 0.00017190672 | BV8: 8.4187968 | BW8: 0.00022847879 | BX8: 0.00010221801 | BY8: 7.5769171 | BZ8: 0.00013687177 | CA8: 0.00012309505 | CB8: 9.0923005 | CC8: 0.00016455702 | CD8: 0.00016069631 | CE8: 11.786315 | CF8: 0.00021427259
A9: 0.027166137 | B9: 172.01246 | C9: -0.0088552735 | E9: 0.033715108 | F9: 194.858 | G9: -0.0097880631 | I9: 0.034205231 | J9: 271.36658 | K9: -0.0090782556 | M9: 0.024151837 | N9: 296.94752 | O9: -0.0051806668 | Q9: 0.032711175 | R9: 399.40631 | S9: -0.0097850631 | U9: 0.0322049 | V9: 421.03047 | W9: -0.0029375005 | Y9: 0.023150846 | Z9: 536.83102 | AA9: -0.00057853593 | AC9: 0.031208062 | AD9: 685.2463 | AE9: -0.0036960244 | AG9: 0.039294383 | AH9: 775.34232 | AI9: -0.0020348591 | AK9: 0.012082623 | AL9: 693.31514 | AM9: 0.0020753325 | AO9: 0.014601241 | AP9: 780.45044 | AQ9: 0.0015639905 | AS9: 0.024177314 | AT9: 852.29234 | AU9: 0.0013847647 | AW9: 0.00013018437 | AX9: 2.3047631 | AY9: 8.998721e-05 | AZ9: 0.00017043126 | BA9: 3.0250016 | BB9: 0.00011783373 | BC9: 0.00028756562 | BD9: 5.1445605 | BE9: 0.0001990057 | BF9: 0.0001070885 | BG9: 3.7863965 | BH9: 7.402126e-05 | BI9: 0.0001336395 | BJ9: 4.7329956 | BK9: 9.2382089e-05 | BL9: 0.00018531597 | BM9: 6.5850374 | BN9: 0.00012814153 | BO9: 0.00013386003 | BP9: 6.5850374 | BQ9: 0.00017903109 | BR9: 0.00016382702 | BS9: 8.0255143 | BT9: 0.00021854389 | BU9: 0.0002117541 | BV9: 10.289121 | BW9: 0.00028153074 | BX9: 0.00012552984 | BY9: 9.2602089 | BZ9: 0.00016815366 | CA9: 0.00015131705 | CB9: 11.112251 | CC9: 0.00020236266 | CD9: 0.00019789666 | CE9: 14.404769 | CF9: 0.00026394701
A10: 0.031693827 | B10: 170.80509 | C10: -0.010983493 | E10: 0.04478574 | F10: 191.44319 | G10: -0.012376253 | I10: 0.044265594 | J10: 269.33937 | K10: -0.012701506 | M10: 0.033208777 | N10: 292.75483 | O10: -0.0098439389 | Q10: 0.043279401 | R10: 408.83524 | S10: -0.014795284 | U10: 0.041765729 | V10: 438.65304 | W10: -0.0057002297 | Y10: 0.030196755 | Z10: 537.69992 | AA10: -0.0028792253 | AC10: 0.041275179 | AD10: 700.29549 | AE10: -0.0091155138 | AG10: 0.050881188 | AH10: 812.17938 | AI10: -0.0053879823 | AK10: 0.015606721 | AL10: 766.52293 | AM10: 0.0013274042 | AO10: 0.019132661 | AP10: 878.62823 | AQ10: 0.00064042716 | AS10: 0.030221642 | AT10: 931.11725 | AU10: 0.0011550964 | AW10: 0.00015362954 | AX10: 2.7237157 | AY10: 0.00010619842 | AZ10: 0.00020102168 | BA10: 3.5748769 | BB10: 0.00013900272 | BC10: 0.00033861735 | BD10: 6.0797226 | BE10: 0.00023447034 | BF10: 0.00012640785 | BG10: 4.4746758 | BH10: 8.7377449e-05 | BI10: 0.000157698 | BJ10: 5.5933448 | BK10: 0.00010902077 | BL10: 0.00021853066 | BM10: 7.7820449 | BN10: 0.00015113875 | BO10: 0.00015894207 | BP10: 7.7820449 | BQ10: 0.00021258833 | BR10: 0.00019471786 | BS10: 9.4843672 | BT10: 0.00025973719 | BU10: 0.00025210774 | BV10: 12.159445 | BW10: 0.0003350764 | BX10: 0.00014902915 | BY10: 10.943501 | BZ10: 0.00019964758 | CA10: 0.00017981269 | CB10: 13.132201 | CC10: 0.00024046844 | CD10: 0.00023557317 | CE10: 17.023223 | CF10: 0.00031411997
A11: 0.0387369 | B11: 167.50761 | C11: -0.013971057 | E11: 0.048308214 | F11: 198.17722 | G11: -0.013411529 | I11: 0.054828974 | J11: 253.22025 | K11: -0.015231072 | M11: 0.043775205 | N11: 286.76652 | O11: -0.014332506 | Q11: 0.053847627 | R11: 402.04646 | S11: -0.021540589 | U11: 0.05182976 | V11: 420.46616 | W11: -0.0091553218 | Y11: 0.036236106 | Z11: 556.64973 | AA11: -0.0046686504 | AC11: 0.05939599 | AD11: 691.08209 | AE11: -0.01337705 | AG11: 0.060452897 | AH11: 840.68982 | AI11: -0.0089101138 | AK11: 0.020137704 | AL11: 780.24884 | AM11: -0.00028973797 | AO11: 0.028698991 | AP11: 958.19973 | AQ11: -0.0023662098 | AS11: 0.041302911 | AT11: 1068.2889 | AU11: -0.00098622269 | AW11: 0.00017700657 | AX11: 3.1426683 | AY11: 0.00012236522 | AZ11: 0.00023148855 | BA11: 4.1247522 | BB11: 0.00016009605 | BC11: 0.0003892671 | BD11: 7.0148847 | BE11: 0.00026972311 | BF11: 0.0001456818 | BG11: 5.1629551 | BH11: 0.00010070348 | BI11: 0.0001816832 | BJ11: 6.4536939 | BK11: 0.00012561267 | BL11: 0.00025159427 | BM11: 8.9790524 | BN11: 0.00017404669 | BO11: 0.00018422783 | BP11: 8.9790524 | BQ11: 0.00024635768 | BR11: 0.00022590985 | BS11: 10.94322 | BT11: 0.00030122594 | BU11: 0.00029297043 | BV11: 14.029769 | BW11: 0.00038908946 | BX11: 0.00017271721 | BY11: 12.626792 | BZ11: 0.00023134787 | CA11: 0.00020858389 | CB11: 15.152151 | CC11: 0.00027886457 | CD11: 0.00027372921 | CE11: 19.641677 | CF11: 0.00036477013
A12: 0.051816892 | B12: 169.67136 | C12: -0.01747557 | E12: 0.056359583 | F12: 208.51943 | G12: -0.015771151 | I12: 0.065392354 | J12: 252.70495 | K12: -0.016781018 | M12: 0.060379594 | N12: 283.28057 | O12: -0.016408805 | Q12: 0.061396359 | R12: 381.86176 | S12: -0.025911923 | U12: 0.060887388 | V12: 433.25288 | W12: -0.011918051 | Y12: 0.041772178 | Z12: 571.39401 | AA12: -0.006686799 | AC12: 0.066442972 | AD12: 680.53572 | AE12: -0.014992799 | AG12: 0.070024606 | AH12: 853.21307 | AI12: -0.010836808 | AK12: 0.02315836 | AL12: 814.12216 | AM12: -0.0012128566 | AO12: 0.034237393 | AP12: 995.01988 | AQ12: -0.0042672673 | AS12: 0.053391568 | AT12: 1178.7423 | AU12: -0.0030127077 | AW12: 0.00020031525 | AX12: 3.5616209 | AY12: 0.00013848784 | AZ12: 0.00026183062 | BA12: 4.6746275 | BB12: 0.00018111425 | BC12: 0.00043950653 | BD12: 7.9500468 | BE12: 0.00030476652 | BF12: 0.00016491029 | BG12: 5.8512344 | BH12: 0.00011399948 | BI12: 0.00020559466 | BJ12: 7.314043 | BK12: 0.00014215806 | BL12: 0.00028450465 | BM12: 10.17606 | BN12: 0.00019686604 | BO12: 0.00020971852 | BP12: 10.17606 | BQ12: 0.00028033233 | BR12: 0.00025740464 | BS12: 12.402073 | BT12: 0.00034299779 | BU12: 0.00033434443 | BV12: 15.900094 | BW12: 0.00044354387 | BX12: 0.00019659524 | BY12: 14.310084 | BZ12: 0.00026324891 | CA12: 0.00023763244 | CB12: 17.172101 | CC12: 0.00031754132 | CD12: 0.00031236775 | CE12: 22.260131 | CF12: 0.00041587624
A13: 0.056847658 | B13: 171.96782 | C13: -0.01908684 | E13: 0.061894899 | F13: 185.14343 | G13: -0.017559355 | I13: 0.075452716 | J13: 257.22677 | K13: -0.019082453 | M13: 0.066417553 | N13: 274.97048 | O13: -0.018189449 | Q13: 0.067435346 | R13: 370.74089 | S13: -0.02833297 | U13: 0.070951419 | V13: 440.97536 | W13: -0.014223686 | Y13: 0.048314808 | Z13: 565.15913 | AA13: -0.0088731266 | AC13: 0.077013445 | AD13: 653.82011 | AE13: -0.016494098 | AG13: 0.079596315 | AH13: 878.60405 | AI13: -0.012871667 | AK13: 0.028696229 | AL13: 858.95303 | AM13: -0.0025402608 | AO13: 0.040279285 | AP13: 1029.6505 | AQ13: -0.0068087519 | AS13: 0.061450673 | AT13: 1214.991 | AU13: -0.0049176035 | AW13: 0.00022355534 | AX13: 3.9805736 | AY13: 0.00015456654 | AZ13: 0.00029204673 | BA13: 5.2245028 | BB13: 0.00020205785 | BC13: 0.00048932825 | BD13: 8.8852089 | BE13: 0.00033960304 | BF13: 0.00018409324 | BG13: 6.5395137 | BH13: 0.00012726559 | BI13: 0.00022943193 | BJ13: 8.1743921 | BK13: 0.00015865718 | BL13: 0.00031725982 | BM13: 11.373067 | BN13: 0.00021959749 | BO13: 0.00023541528 | BP13: 11.373067 | BQ13: 0.00031450549 | BR13: 0.00028920371 | BS13: 13.860926 | BT13: 0.00038504046 | BU13: 0.00037623156 | BV13: 17.770418 | BW13: 0.00049841383 | BX13: 0.00022066439 | BY13: 15.993376 | BZ13: 0.00029534512 | CA13: 0.00026695999 | CB13: 19.192051 | CC13: 0.00035648903 | CD13: 0.00035149135 | CE13: 24.878585 | CF13: 0.00046741722
A14: 0.064393807 | B14: 164.69338 | C14: -0.022134827 | E14: 0.065920584 | F14: 189.47823 | G14: -0.018655134 | I14: 0.085513078 | J14: 260.06969 | K14: -0.020746464 | M14: 0.074468165 | N14: 271.8724 | O14: -0.020319502 | Q14: 0.080016567 | R14: 376.44578 | S14: -0.031789686 | U14: 0.080512249 | V14: 436.34053 | W14: -0.01560169 | Y14: 0.055863997 | Z14: 540.67043 | AA14: -0.012909424 | AC14: 0.089597341 | AD14: 646.60568 | AE14: -0.017705909 | AG14: 0.090679346 | AH14: 889.60338 | AI14: -0.014629352 | AK14: 0.035240982 | AL14: 863.39058 | AM14: -0.0047301409 | AO14: 0.04732816 | AP14: 1021.0619 | AQ14: -0.012006324 | AS14: 0.069509777 | AT14: 1269.9708 | AU14: -0.0059646208 | AW14: 0.00024672665 | AX14: 4.3995262 | AY14: 0.00017060154 | AZ14: 0.00032213578 | BA14: 5.7743781 | BB14: 0.00022292738 | BC14: 0.00053872584 | BD14: 9.8203709 | BE14: 0.0003742351 | BF14: 0.0002032306 | BG14: 7.227793 | BH14: 0.00014050195 | BI14: 0.00025319459 | BJ14: 9.0347413 | BK14: 0.0001751103 | BL14: 0.0003498579 | BM14: 12.570075 | BN14: 0.00024224172 | BO14: 0.00026131918 | BP14: 12.570075 | BQ14: 0.00034887046 | BR14: 0.00032130838 | BS14: 15.319779 | BT14: 0.00042734184 | BU14: 0.00041863317 | BV14: 19.640742 | BW14: 0.00055367379 | BX14: 0.00024492576 | BY14: 17.676668 | BZ14: 0.00032763094 | CA14: 0.00029656805 | CB14: 21.212001 | CC14: 0.00039569811 | CD14: 0.00039110214 | CE14: 27.497039 | CF14: 0.00051937214
... A44: 0.12022133 | B44: 153.12148 | C44: -0.026087404 | E44: 0.096091288 | F44: 190.94713 | G44: -0.032788873 | I44: 0.20020121 | J44: 306.44144 | K44: -0.035870181 | M44: 0.12883026 | N44: 262.25952 | O44: -0.015863692 | Q44: 0.14691776 | R44: 299.25686 | S44: -0.031245693 | U44: 0.12831123 | V44: 504.47328 | W44: -0.022446855 | Y44: 0.13334841 | Z44: 507.55908 | AA44: -0.027351692 | AC44: 0.18021188 | AD44: 633.7266 | AE44: -0.034715034 | AG44: 0.17066513 | AH44: 937.89393 | AI44: -0.016386123 | AK44: 0.10224821 | AL44: 809.9715 | AM44: -0.017468077 | AO44: 0.11527055 | AP44: 970.5665 | AQ44: -0.029173604 | AS44: 0.10171317 | AT44: 1160.1977 | AU44: -0.016239509 | AW44: 0.00090940171 | AX44: 16.968105 | AY44: 0.00063244427 | AZ44: 0.0011629502 | BA44: 22.270637 | BB44: 0.00081697772 | BC44: 0.0018196183 | BD44: 37.875234 | BE44: 0.0013286354 | BF44: 0.00075601481 | BG44: 27.876172 | BH44: 0.00052438603 | BI44: 0.00093012073 | BJ44: 34.845215 | BK44: 0.00064850969 | BL44: 0.0012500766 | BM44: 48.480299 | BN44: 0.00088406291 | BO44: 0.0011375121 | BP44: 48.480299 | BQ44: 0.0014381106 | BR44: 0.0014276081 | BS44: 59.085365 | BT44: 0.0017617307 | BU44: 0.0019217282 | BV44: 75.750468 | BW44: 0.0022808068 | BX44: 0.0010653756 | BY44: 68.175421 | BZ44: 0.0013585873 | CA44: 0.0013181095 | CB44: 81.810505 | CC44: 0.0016492699 | CD44: 0.0018032953 | CE44: 106.05065 | CF44: 0.0021762425
A45: 0.13430584 | B45: 115.57207 | C45: -0.028670648 | E45: 0.1187306 | F45: 163.6178 | G45: -0.035320392 | M45: 0.13839188 | N45: 265.30363 | O45: -0.016684112 | Q45: 0.15949634 | R45: 277.72931 | S45: -0.03222653 | U45: 0.13736849 | V45: 515.49038 | W45: -0.023770816 | Y45: 0.14290924 | Z45: 531.08433 | AA45: -0.028386875 | AC45: 0.19329989 | AD45: 651.11027 | AE45: -0.035698234 | AG45: 0.17872012 | AH45: 949.01971 | AI45: -0.016824075 | AK45: 0.1133293 | AL45: 803.09835 | AM45: -0.019232738 | AO45: 0.12382776 | AP45: 966.17292 | AQ45: -0.030035413 | AS45: 0.10926612 | AT45: 1183.4824 | AU45: -0.017224131 | AW45: 0.0009304077 | AX45: 17.387057 | AY45: 0.00064723344 | AZ45: 0.0011888975 | BA45: 22.820513 | BB45: 0.00083578532 | BC45: 0.0018561084 | BD45: 38.810396 | BE45: 0.0013579364 | BF45: 0.00077373061 | BG45: 28.564451 | BH45: 0.00053676185 | BI45: 0.00095146809 | BJ45: 35.705564 | BK45: 0.00066365385 | BL45: 0.0012774637 | BM45: 49.677307 | BN45: 0.00090429982 | BO45: 0.001170041 | BP45: 49.677307 | BQ45: 0.0014754152 | BR45: 0.0014691426 | BS45: 60.544218 | BT45: 0.0018067493 | BU45: 0.0019788995 | BV45: 77.620792 | BW45: 0.002337523 | BX45: 0.0010958553 | BY45: 69.858713 | BZ45: 0.0013942322 | CA45: 0.0013565698 | CB45: 83.830455 | CC45: 0.0016922841 | CD45: 0.0018574027 | CE45: 108.66911 | CF45: 0.0022319956
A46: 0.138833 | B46: 138.24627 | C46: -0.028784713 | E46: 0.12325846 | F46: 188.69308 | G46: -0.035320392 | M46: 0.15348918 | N46: 258.02873 | O46: -0.01728934 | Q46: 0.17056548 | R46: 296.61726 | S46: -0.032858027 | U46: 0.14642576 | V46: 518.78695 | W46: -0.024516804 | Y46: 0.15599248 | Z46: 511.49608 | AA46: -0.029482556 | AC46: 0.20286421 | AD46: 662.18168 | AE46: -0.036331253 | AG46: 0.18878886 | AH46: 952.90515 | AI46: -0.017208124 | AK46: 0.12541776 | AL46: 782.68757 | AM46: -0.021175924 | AO46: 0.13288832 | AP46: 937.16709 | AQ46: -0.031476251 | AS46: 0.11782614 | AT46: 1178.4122 | AU46: -0.018707807 | AW46: 0.00095134458 | AX46: 17.80601 | AY46: 0.00066198564 | AZ46: 0.0012147133 | BA46: 23.370388 | BB46: 0.00085453316 | BC46: 0.0018922528 | BD46: 39.745558 | BE46: 0.0013870926 | BF46: 0.00079140096 | BG46: 29.252731 | BH46: 0.00054911177 | BI46: 0.00097273709 | BJ46: 36.565913 | BK46: 0.00067875925 | BL46: 0.0013046863 | BM46: 50.874314 | BN46: 0.00092446757 | BO46: 0.0012027816 | BP46: 50.874314 | BQ46: 0.0015127285 | BR46: 0.0015109628 | BS46: 62.00307 | BT46: 0.0018517101 | BU46: 0.0020364708 | BV46: 79.491116 | BW46: 0.0023940187 | BX46: 0.0011265365 | BY46: 71.542004 | BZ46: 0.0014299121 | CA46: 0.0013953057 | CB46: 85.850405 | CC46: 0.0017352994 | CD46: 0.0019119209 | CE46: 111.28756 | CF46: 0.0022876331
A47: 0.15392354 | B47: 124.93536 | C47: -0.031367956 | E47: 0.13281728 | F47: 190.27996 | G47: -0.035891158 | M47: 0.16405729 | N47: 248.76455 | O47: -0.018271154 | Q47: 0.1836472 | R47: 290.25872 | S47: -0.033261111 | U47: 0.15548302 | V47: 526.66066 | W47: -0.025901251 | Y47: 0.17159173 | Z47: 477.42933 | AA47: -0.031263878 | AG47: 0.19835417 | AH47: 942.69085 | AI47: -0.017699978 | AK47: 0.13750621 | AL47: 780.14752 | AM47: -0.022995515 | AO47: 0.14245226 | AP47: 920.89949 | AQ47: -0.032284198 | AS47: 0.12638616 | AT47: 1184.3509 | AU47: -0.020022883 | AW47: 0.00097221249 | AX47: 18.224963 | AY47: 0.00067670105 | AZ47: 0.0012403982 | BA47: 23.920263 | BB47: 0.00087322164 | BC47: 0.0019280576 | BD47: 40.68072 | BE47: 0.0014161054 | BF47: 0.0008090259 | BG47: 29.94101 | BH47: 0.00056143589 | BI47: 0.00099392786 | BJ47: 37.426262 | BK47: 0.00069382609 | BL47: 0.0013317454 | BM47: 52.071322 | BN47: 0.00094456662 | BO47: 0.0012357335 | BP47: 52.071322 | BQ47: 0.0015500459 | BR47: 0.0015530669 | BS47: 63.461923 | BT47: 0.0018966055 | BU47: 0.002094436 | BV47: 81.36144 | BW47: 0.0024502821 | BX47: 0.0011574188 | BY47: 73.225296 | BZ47: 0.0014656229 | CA47: 0.0014343158 | CB47: 87.870355 | CC47: 0.0017783094 | CD47: 0.0019668451 | CE47: 113.90602 | CF47: 0.0023431438
A48: 0.16348089 | B48: 129.10998 | C48: -0.032287189 | E48: 0.141873 | F48: 171.42509 | G48: -0.036985688 | M48: 0.1746254 | N48: 252.09609 | O48: -0.018762061 | Q48: 0.20176035 | R48: 268.80849 | S48: -0.034584568 | U48: 0.16504346 | V48: 534.44525 | W48: -0.027285698 | Y48: 0.18215896 | Z48: 506.01009 | AA48: -0.031841967 | AK48: 0.15060204 | AL48: 770.72101 | AM48: -0.024876904 | AO48: 0.15201619 | AP48: 921.0614 | AQ48: -0.033152741 | AS48: 0.13544971 | AT48: 1179.6118 | AU48: -0.021776319 | AW48: 0.00099301157 | AX48: 18.643915 | AY48: 0.00069137986 | AZ48: 0.0012659529 | BA48: 24.470139 | BB48: 0.00089185111 | BC48: 0.0019635287 | BD48: 41.615882 | BE48: 0.0014449762 | BF48: 0.0008266055 | BG48: 30.629289 | BH48: 0.00057373433 | BI48: 0.0010150405 | BJ48: 38.286612 | BK48: 0.00070885455 | BL48: 0.001358642 | BM48: 53.268329 | BN48: 0.00096459745 | BO48: 0.0012688961 | BP48: 53.268329 | BQ48: 0.0015873627 | BR48: 0.0015954528 | BS48: 64.920776 | BT48: 0.0019414282 | BU48: 0.0021527893 | BV48: 83.231764 | BW48: 0.0025063017 | BX48: 0.0011885019 | BY48: 74.908588 | BZ48: 0.0015013606 | CA48: 0.0014735987 | CB48: 89.890305 | CC48: 0.0018213078 | CD48: 0.0020221703 | CE48: 116.52447 | CF48: 0.0023985168
A49: 0.16851107 | B49: 137.36973 | C49: -0.032287189 | E49: 0.15595968 | F49: 168.75483 | G49: -0.038019783 | M49: 0.18569675 | N49: 249.59238 | O49: -0.019528683 | U49: 0.17460391 | V49: 528.56427 | W49: -0.028777674 | Y49: 0.18970699 | Z49: 500.89017 | AA49: -0.032588106 | AK49: 0.16369787 | AL49: 726.84774 | AM49: -0.027582259 | AO49: 0.16158012 | AP49: 913.45099 | AQ49: -0.033960687 | AS49: 0.14753444 | AT49: 1178.5482 | AU49: -0.022990235 | AW49: 0.001013742 | AX49: 19.062868 | AY49: 0.00070602224 | AZ49: 0.0012913778 | BA49: 25.020014 | BB49: 0.00091042195 | BC49: 0.0019986721 | BD49: 42.551044 | BE49: 0.0014737065 | BF49: 0.00084413983 | BG49: 31.317569 | BH49: 0.00058600719 | BI49: 0.0010360752 | BJ49: 39.146961 | BK49: 0.00072384483 | BL49: 0.001385377 | BM49: 54.465337 | BN49: 0.00098456052 | BO49: 0.0013022688 | BP49: 54.465337 | BQ49: 0.0016246745 | BR49: 0.0016381185 | BS49: 66.379629 | BT49: 0.0019861713 | BU49: 0.0022115244 | BV49: 85.102089 | BW49: 0.0025620667 | BX49: 0.0012197854 | BY49: 76.59188 | BZ49: 0.0015371213 | CA49: 0.001513153 | CB49: 91.910256 | CC49: 0.0018642882 | CD49: 0.0020778915 | CE49: 119.14292 | CF49: 0.0024537414
A50: 0.18008048 | B50: 120.41464 | C50: -0.033380873 | E50: 0.16048754 | F50: 177.73296 | G50: -0.038080217 | M50: 0.19576161 | N50: 255.2664 | O50: -0.019804397 | U50: 0.18416435 | V50: 526.95287 | W50: -0.030619123 | Y50: 0.19876461 | Z50: 478.80488 | AA50: -0.033280469 | AK50: 0.17830476 | AL50: 718.87797 | AM50: -0.028179634 | AO50: 0.17164742 | AP50: 922.4036 | AQ50: -0.034418523 | AS50: 0.15861211 | AT50: 1191.8182 | AU50: -0.02359045 | AW50: 0.0010344039 | AX50: 19.48182 | AY50: 0.00072062838 | AZ50: 0.0013166737 | BA50: 25.569889 | BB50: 0.00092893454 | BC50: 0.0020334937 | BD50: 43.486206 | BE50: 0.0015022976 | BF50: 0.00086162895 | BG50: 32.005848 | BH50: 0.00059825458 | BI50: 0.0010570321 | BJ50: 40.00731 | BK50: 0.00073879714 | BL50: 0.0014119514 | BM50: 55.662344 | BN50: 0.0010044563 | BO50: 0.001335851 | BP50: 55.662344 | BQ50: 0.0016619766 | BR50: 0.0016810622 | BS50: 67.838482 | BT50: 0.0020308276 | BU50: 0.0022706355 | BV50: 86.972413 | BW50: 0.0026175662 | BX50: 0.0012512689 | BY50: 78.275171 | BZ50: 0.0015729009 | CA50: 0.0015529773 | CB50: 93.930206 | CC50: 0.0019072447 | CD50: 0.0021340036 | CE50: 121.76138 | CF50: 0.0025088074
A51: 0.18561368 | B51: 130.96158 | C51: -0.033266808 | E51: 0.18614543 | F51: 169.04912 | G51: -0.037334863 | M51: 0.20180053 | N51: 247.43653 | O51: -0.020571019 | U51: 0.19825343 | V51: 531.28678 | W51: -0.033730768 | Y51: 0.20329343 | Z51: 490.27631 | AA51: -0.033219971 | AK51: 0.19240796 | AL51: 707.70089 | AM51: -0.029353786 | AO51: 0.18221808 | AP51: 897.43994 | AQ51: -0.035051415 | AS51: 0.16868272 | AT51: 1194.1817 | AU51: -0.024581815 | AW51: 0.0010549974 | AX51: 19.900773 | AY51: 0.00073519845 | AZ51: 0.0013418412 | BA51: 26.119765 | BB51: 0.00094738923 | BC51: 0.0020679994 | BD51: 44.421368 | BE51: 0.0015307508 | BF51: 0.00087907294 | BG51: 32.694127 | BH51: 0.00061047661 | BI51: 0.0010779114 | BJ51: 40.867659 | BK51: 0.00075371165 | BL51: 0.0014383663 | BM51: 56.859352 | BN51: 0.0010242852 | BO51: 0.001369642 | BP51: 56.859352 | BQ51: 0.0016992647 | BR51: 0.0017242817 | BS51: 69.297335 | BT51: 0.0020753903 | BU51: 0.0023301165 | BV51: 88.842737 | BW51: 0.0026727902 | BX51: 0.001282952 | BY51: 79.958463 | BZ51: 0.0016086958 | CA51: 0.0015930701 | CB51: 95.950156 | CC51: 0.001950171 | CD51: 0.0021905017 | CE51: 124.37983 | CF51: 0.0025637047
A52: 0.19768612 | B52: 131.11234 | C52: -0.034011587 | E52: 0.19067329 | F52: 185.49873 | G52: -0.037334863 | AK52: 0.20298536 | AL52: 698.9006 | AM52: -0.029882497 | AO52: 0.19329211 | AP52: 858.95056 | AQ52: -0.036209472 | AS52: 0.18076746 | AT52: 1165.8904 | AU52: -0.026058747 | AW52: 0.0010755228 | AX52: 20.319726 | AY52: 0.00074973263 | AZ52: 0.0013668809 | BA52: 26.66964 | BB52: 0.00096578638 | BC52: 0.0021021951 | BD52: 45.356531 | BE52: 0.0015590675 | BF52: 0.00089647186 | BG52: 33.382406 | BH52: 0.00062267337 | BI52: 0.0010987132 | BJ52: 41.728008 | BK52: 0.00076858856 | BL52: 0.0014646228 | BM52: 58.056359 | BN52: 0.0010440477 | BO52: 0.0014036413 | BP52: 58.056359 | BQ52: 0.0017365345 | BR52: 0.0017677749 | BS52: 70.756188 | BT52: 0.0021198528 | BU52: 0.0023899612 | BV52: 90.713061 | BW52: 0.0027277289 | BX52: 0.0013148343 | BY52: 81.641755 | BZ52: 0.0016445019 | CA52: 0.0016334298 | CB52: 97.970106 | CC52: 0.0019930615 | CD52: 0.0022473805 | CE52: 126.99829 | CF52: 0.0026184236
AO53: 0.20184931 | AP53: 884.24191 | AQ53: -0.035805498 | AS53: 0.1913416 | AT53: 1173.4977 | AU53: -0.026227347 | AW53: 0.0010959802 | AX53: 20.738678 | AY53: 0.00076423111 | AZ53: 0.0013917936 | BA53: 27.219515 | BB53: 0.00098412636 | BC53: 0.0021360864 | BD53: 46.291693 | BE53: 0.0015872489 | BF53: 0.0009138258 | BG53: 34.070686 | BH53: 0.00063484498 | BI53: 0.0011194377 | BJ53: 42.588357 | BK53: 0.00078342806 | BL53: 0.0014907219 | BM53: 59.253367 | BN53: 0.0010637442 | BO53: 0.0014378481 | BP53: 59.253367 | BQ53: 0.0017737815 | BR53: 0.0018115398 | BS53: 72.215041 | BT53: 0.0021642084 | BU53: 0.0024501638 | BV53: 92.583385 | BW53: 0.0027823727 | BX53: 0.0013469153 | BY53: 83.325047 | BZ53: 0.0016803155 | CA53: 0.0016740549 | CB53: 99.990056 | CC53: 0.0020359101 | CD53: 0.002304635 | CE53: 129.61674 | CF53: 0.0026729549
AS54: 0.20443339 | AT54: 1160.8054 | AU54: -0.027104065 | AW54: 0.0011163698 | AX54: 21.157631 | AY54: 0.00077869405 | AZ54: 0.0014165799 | BA54: 27.769391 | BB54: 0.0010024095 | BC54: 0.0021696792 | BD54: 47.226855 | BE54: 0.0016152964 | BF54: 0.00093113482 | BG54: 34.758965 | BH54: 0.00064699153 | BI54: 0.0011400852 | BJ54: 43.448706 | BK54: 0.00079823033 | BL54: 0.0015166649 | BM54: 60.450374 | BN54: 0.0010833752 | BO54: 0.0014722617 | BP54: 60.450374 | BQ54: 0.0018110016 | BR54: 0.0018555742 | BS54: 73.673893 | BT54: 0.0022084509 | BU54: 0.0025107183 | BV54: 94.453709 | BW54: 0.0028367128 | BX54: 0.0013791944 | BY54: 85.008339 | BZ54: 0.001716133 | CA54: 0.001714944 | CB54: 102.01001 | CC54: 0.0020787113 | CD54: 0.0023622602 | CE54: 132.23519 | CF54: 0.0027272895
AW55: 0.0011366918 | AX55: 21.576584 | AY55: 0.00079312162 | AZ55: 0.0014412407 | BA55: 28.319266 | BB55: 0.0010206362 | BC55: 0.0022029791 | BD55: 48.162017 | BE55: 0.0016432112 | BF55: 0.00094839902 | BG55: 35.447244 | BH55: 0.00065911313 | BI55: 0.0011606557 | BJ55: 44.309055 | BK55: 0.00081299557 | BL55: 0.0015424529 | BM55: 61.647382 | BN55: 0.0011029411 | BO55: 0.0015068815 | BP55: 61.647382 | BQ55: 0.0018481906 | BR55: 0.0018998761 | BS55: 75.132746 | BT55: 0.0022525739 | BU55: 0.0025716186 | BV55: 96.324034 | BW55: 0.0028907403 | BX55: 0.0014116713 | BY55: 86.69163 | BZ55: 0.0017519505 | CA55: 0.0017560952 | CB55: 104.02996 | CC55: 0.0021214594 | CD55: 0.0024202508 | CE55: 134.85365 | CF55: 0.0027814186
AW56: 0.0011569463 | AX56: 21.995536 | AY56: 0.00080751401 | AZ56: 0.0014657767 | BA56: 28.869141 | BB56: 0.0010388068 | BC56: 0.0022359916 | BD56: 49.097179 | BE56: 0.0016709945 | BF56: 0.00096561848 | BG56: 36.135524 | BH56: 0.00067120988 | BI56: 0.0011811496 | BJ56: 45.169405 | BK56: 0.00082772396 | BL56: 0.0015680871 | BM56: 62.844389 | BN56: 0.0011224424 | BO56: 0.0015417066 | BP56: 62.844389 | BQ56: 0.0018853444 | BR56: 0.0019444431 | BS56: 76.591599 | BT56: 0.0022965713 | BU56: 0.0026328589 | BV56: 98.194358 | BW56: 0.002944447 | BX56: 0.0014443454 | BY56: 88.374922 | BZ56: 0.0017877646 | CA56: 0.0017975071 | CB56: 106.04991 | CC56: 0.0021641489 | CD56: 0.0024786018 | CE56: 137.4721 | CF56: 0.0028353338
AW57: 0.0011771337 | AX57: 22.414489 | AY57: 0.00082187138 | AZ57: 0.0014901885 | BA57: 29.419017 | BB57: 0.0010569215 | BC57: 0.0022687222 | BD57: 50.032341 | BE57: 0.0016986477 | BF57: 0.00098279327 | BG57: 36.823803 | BH57: 0.00068328189 | BI57: 0.0012015671 | BJ57: 46.029754 | BK57: 0.00084241568 | BL57: 0.0015935686 | BM57: 64.041397 | BN57: 0.0011418794 | BO57: 0.0015767363 | BP57: 64.041397 | BQ57: 0.0019224588 | BR57: 0.0019892732 | BS57: 78.050452 | BT57: 0.0023404372 | BU57: 0.0026944332 | BV57: 100.06468 | BW57: 0.002997825 | BX57: 0.0014772161 | BY57: 90.058214 | BZ57: 0.0018235714 | CA57: 0.0018391779 | CB57: 108.06986 | CC57: 0.0022067744 | CD57: 0.0025373081 | CE57: 140.09055 | CF57: 0.0028890268
AW58: 0.001197254 | AX58: 22.833441 | AY58: 0.0008361939 | AZ58: 0.0015144771 | BA58: 29.968892 | BB58: 0.0010749809 | BC58: 0.0023011763 | BD58: 50.967503 | BE58: 0.0017261718 | BF58: 0.00099992349 | BG58: 37.512082 | BH58: 0.00069532925 | BI58: 0.0012219083 | BJ58: 46.890103 | BK58: 0.00085707091 | BL58: 0.0016188989 | BM58: 65.238404 | BN58: 0.0011612526 | BO58: 0.0016119699 | BP58: 65.238404 | BQ58: 0.00195953 | BR58: 0.0020343641 | BS58: 79.509305 | BT58: 0.0023841657 | BU58: 0.0027563358 | BV58: 101.93501 | BW58: 0.0030508667 | BX58: 0.0015102829 | BY58: 91.741506 | BZ58: 0.0018593677 | CA58: 0.001881106 | CB58: 110.08981 | CC58: 0.0022493308 | CD58: 0.0025963646 | CE58: 142.70901 | CF58: 0.0029424899
AW59: 0.0012173075 | AX59: 23.252394 | AY59: 0.00085048174 | AZ59: 0.0015386432 | BA59: 30.518767 | BB59: 0.0010929851 | BC59: 0.0023333594 | BD59: 51.902665 | BE59: 0.0017535682 | BF59: 0.0010170092 | BG59: 38.200362 | BH59: 0.00070735206 | BI59: 0.0012421736 | BJ59: 47.750452 | BK59: 0.00087168983 | BL59: 0.001644079 | BM59: 66.435411 | BN59: 0.0011805625 | BO59: 0.0016474065 | BP59: 66.435411 | BQ59: 0.0019965539 | BR59: 0.0020797136 | BS59: 80.968158 | BT59: 0.0024277512 | BU59: 0.0028185607 | BV59: 103.80533 | BW59: 0.0031035648 | BX59: 0.0015435452 | BY59: 93.424797 | BZ59: 0.0018951497 | CA59: 0.0019232898 | CB59: 112.10976 | CC59: 0.0022918127 | CD59: 0.0026557663 | CE59: 145.32746 | CF59: 0.0029957155
AW60: 0.0012372944 | AX60: 23.671347 | AY60: 0.00086473507 | AZ60: 0.0015626877 | BA60: 31.068642 | BB60: 0.0011109346 | BC60: 0.0023652764 | BD60: 52.837827 | BE60: 0.0017808379 | BF60: 0.0010340506 | BG60: 38.888641 | BH60: 0.00071935043 | BI60: 0.0012623631 | BJ60: 48.610801 | BK60: 0.00088627263 | BL60: 0.0016691103 | BM60: 67.632419 | BN60: 0.0011998093 | BO60: 0.0016830454 | BP60: 67.632419 | BQ60: 0.0020335268 | BR60: 0.0021253195 | BS60: 82.427011 | BT60: 0.002471188 | BU60: 0.0028811024 | BV60: 105.67565 | BW60: 0.0031559124 | BX60: 0.0015770024 | BY60: 95.108089 | BZ60: 0.0019309141 | CA60: 0.0019657273 | CB60: 114.12971 | CC60: 0.0023342151 | CD60: 0.002715508 | CE60: 147.94592 | CF60: 0.0030486962
AW61: 0.001257215 | AX61: 24.090299 | AY61: 0.00087895406 | AZ61: 0.0015866113 | BA61: 31.618518 | BB61: 0.0011288297 | BC61: 0.0023969327 | BD61: 53.772989 | BE61: 0.0018079822 | BF61: 0.0010510476 | BG61: 39.57692 | BH61: 0.00073132446 | BI61: 0.0012824772 | BJ61: 49.47115 | BK61: 0.00090081948 | BL61: 0.0016939941 | BM61: 68.829426 | BN61: 0.0012189936 | BO61: 0.0017188857 | BP61: 68.829426 | BQ61: 0.0020704447 | BR61: 0.0021711796 | BS61: 83.885863 | BT61: 0.0025144709 | BU61: 0.0029439551 | BV61: 107.54598 | BW61: 0.003207903 | BX61: 0.0016106539 | BY61: 96.791381 | BZ61: 0.0019666575 | CA61: 0.0020084171 | CB61: 116.14966 | CC61: 0.002376533 | CD61: 0.0027755848 | CE61: 150.56437 | CF61: 0.003101425
AW62: 0.0012770695 | AX62: 24.509252 | AY62: 0.00089313886 | AZ62: 0.001610415 | BA62: 32.168393 | BB62: 0.0011466706 | BC62: 0.0024283333 | BD62: 54.708151 | BE62: 0.0018350022 | BF62: 0.0010680005 | BG62: 40.2652 | BH62: 0.00074327423 | BI62: 0.001302516 | BJ62: 50.331499 | BK62: 0.00091533055 | BL62: 0.0017187316 | BM62: 70.026434 | BN62: 0.0012381156 | BO62: 0.0017549266 | BP62: 70.026434 | BQ62: 0.002107304 | BR62: 0.0022172916 | BS62: 85.344716 | BT62: 0.0025575944 | BU62: 0.0030071131 | BV62: 109.4163 | BW62: 0.0032595302 | BX62: 0.0016444991 | BY62: 98.474673 | BZ62: 0.0020023765 | CA62: 0.0020513572 | CB62: 118.16961 | CC62: 0.0024187616 | CD62: 0.0028359917 | CE62: 153.18282 | CF62: 0.0031538951
AW63: 0.001296858 | AX63: 24.928204 | AY63: 0.00090728965 | AZ63: 0.0016340995 | BA63: 32.718268 | BB63: 0.0011644578 | BC63: 0.002459483 | BD63: 55.643314 | BE63: 0.001861899 | BF63: 0.0010849093 | BG63: 40.953479 | BH63: 0.00075519986 | BI63: 0.00132248 | BJ63: 51.191849 | BK63: 0.00092980603 | BL63: 0.0017433242 | BM63: 71.223441 | BN63: 0.001257176 | BO63: 0.0017911672 | BP63: 71.223441 | BQ63: 0.0021441009 | BR63: 0.0022636533 | BS63: 86.803569 | BT63: 0.0026005535 | BU63: 0.003070571 | BV63: 111.28663 | BW63: 0.0033107883 | BX63: 0.0016785374 | BY63: 100.15796 | BZ63: 0.0020380677 | CA63: 0.002094546 | CB63: 120.18956 | CC63: 0.0024608961 | CD63: 0.0028967236 | CE63: 155.80128 | CF63: 0.0032061001
AW64: 0.0013165809 | AX64: 25.347157 | AY64: 0.00092140658 | AZ64: 0.0016576657 | BA64: 33.268144 | BB64: 0.0011821915 | BC64: 0.0024903867 | BD64: 56.578476 | BE64: 0.0018886738 | BF64: 0.001101774 | BG64: 41.641758 | BH64: 0.00076710143 | BI64: 0.0013423692 | BJ64: 52.052198 | BK64: 0.00094424609 | BL64: 0.0017677732 | BM64: 72.420449 | BN64: 0.0012761749 | BO64: 0.0018276067 | BP64: 72.420449 | BQ64: 0.0021808318 | BR64: 0.0023102623 | BS64: 88.262422 | BT64: 0.0026433431 | BU64: 0.0031343232 | BV64: 113.15695 | BW64: 0.0033616714 | BX64: 0.0017127681 | BY64: 101.84126 | BZ64: 0.0020737281 | CA64: 0.0021379816 | CB64: 122.20951 | CC64: 0.0025029318 | CD64: 0.0029577758 | CE64: 158.41973 | CF64: 0.0032580337
AW65: 0.0013362384 | AX65: 25.76611 | AY65: 0.00093548982 | AZ65: 0.0016811146 | BA65: 33.818019 | BB65: 0.0011998721 | BC65: 0.0025210491 | BD65: 57.513638 | BE65: 0.0019153277 | BF65: 0.0011185949 | BG65: 42.330037 | BH65: 0.00077897905 | BI65: 0.0013621841 | BJ65: 52.912547 | BK65: 0.0009586509 | BL65: 0.00179208 | BM65: 73.617456 | BN65: 0.0012951129 | BO65: 0.0018642443 | BP65: 73.617456 | BQ65: 0.0022174931 | BR65: 0.0023571166 | BS65: 89.721275 | BT65: 0.0026859583 | BU65: 0.0031983644 | BV65: 115.02728 | BW65: 0.0034121743 | BX65: 0.0017471906 | BY65: 103.52455 | BZ65: 0.0021093542 | CA65: 0.0021816623 | CB65: 124.22946 | CC65: 0.0025448641 | CD65: 0.0030191433 | CE65: 161.03819 | CF65: 0.0033096899
AW66: 0.0013558307 | AX66: 26.185062 | AY66: 0.00094953953 | AZ66: 0.001704447 | BA66: 34.367894 | BB66: 0.0012174998 | BC66: 0.002551475 | BD66: 58.4488 | BE66: 0.0019418617 | BF66: 0.0011353719 | BG66: 43.018317 | BH66: 0.00079083281 | BI66: 0.0013819249 | BJ66: 53.772896 | BK66: 0.00097302063 | BL66: 0.0018162458 | BM66: 74.814464 | BN66: 0.0013139903 | BO66: 0.0019010789 | BP66: 74.814464 | BQ66: 0.0022540813 | BR66: 0.0024042137 | BS66: 91.180128 | BT66: 0.0027283945 | BU66: 0.0032626891 | BV66: 116.8976 | BW66: 0.0034622919 | BX66: 0.0017818041 | BY66: 105.20784 | BZ66: 0.0021449429 | CA66: 0.0022255863 | CB66: 126.24941 | CC66: 0.0025866886 | CD66: 0.0030808213 | CE66: 163.65664 | CF66: 0.0033610631
