Workbook

Sheet A
A2: Matrix properties | Z2: 50kpa | AA2: pf
A3: λ* | B3: 0.0164 | C3: po (kPa) | D3: 200 | Z3: 25 | AA3: 102.5
A4: k | B4: 0.006 | C4: qo (kPa) | D4: 0 | Z4: 51 | AA4: 116.7
A5: ϕpk | B5: =IF(R58>=AA58,D9,D9-49.3*(R58-AA58)) -> 34.18269 | C5: dq/dp | D5: 3 | Z5: 100kpa
A6: Po* (kPa) | B6: =IF(D3>170,D3,170) -> 200 | C6: E or C | D6: C | Z6: 25 | AA6: 188.2
A7: vp (1 + ep) | B7: =1+C26 -> 1.603 | C7: pf (kPa) | D7: 400 | Z7: 51 | AA7: 208.5
A8: N | B8: =1.83*((1+K49)/K49)^B3+D22 -> 1.8509214 | C8: Pf Estimated | D8: =IF(D5<0,IF((D5*D3-D4)/(D5-B10)<K49/(1+K49)*B6,K49/(1+K49)*B6,(D5*D3-D4)/(D5-B10)),1.4*SQRT(100/D3)*IF((D5*D3-D4)/(D5-B10)<K49/(1+K49)*B6,K49/(1+K49)*B6,(D5*D3-D4)/(D5-B10))) -> 367.23659 | Z8: 200kpa
A9: νp | B9: 0.15 | C9: ϕcv | D9: 30.5 | Z9: 25 | AA9: 359.1
A10: Mpk | B10: =IF(D6="E",6*SIN(B5*PI()/180)/(3+SIN(B5*PI()/180)),6*SIN(B5*PI()/180)/(3-SIN(B5*PI()/180))) -> 1.3825966 | C10: Mcv | D10: =IF(D6="E",6*SIN(D9*PI()/180)/(3+SIN(D9*PI()/180)),6*SIN(D9*PI()/180)/(3-SIN(D9*PI()/180))) -> 1.2217761 | Z10: 51 | AA10: 392
A11: Fibre Properties | Z11: 300kpa
A12: Pf (%) | C12: 0.5 | D12:  (n/(1+n)) | E12: =K49/(1+K49) -> 0.5 | Z12: 25 | AA12: 524.5
A13: ss | C13: 26.57 | D13:  | E13: =LN(0.5)/LN(E12) -> 1 | Z13: 51 | AA13: 576
A14: sf | C14: 9.1
A15: s | C15: =1/(C12/100/C14+(1-C12/100)/C13) -> 26.317382
A16: sf/s | C16: =C14/C15 -> 0.34577907
A17: aff | C17: =IF(C22=51,2.1,IF(C22=25,1.4,0.8)) -> 2.1
A18: Eufibras (MPa) | C18: 910
A19: νf | C19: 0.25
A20: Tensile strength (MPa) | C20: 225
A21: Ve | C21: =((1-C$12/100)/$C$13)/((1-C$12/100)/$C$13+(C12/100)/10) -> 0.98682416
A22: L (mm) | C22: 51 | E22: 0.61242642 | F22: 0.61079769 | G22: 0.61145784 | H22: 50
E23: 0.606 | F23: 0.6092393 | G23: 0.60643635 | H23: 100
E24: 0.603 | F24: 0.60850339 | G24: 0.61086262 | H24: 200
E25: 0.596 | F25: 0.60781077 | G25: 0.60780536 | H25: 300
A26: e (void ratio after consolidation) | C26: =IF(C12=0,IF(D3=50,G22,IF(D3=100,G23,IF(D3=200,G24,G25))),IF(C22=25,IF(D3=50,F22,IF(D3=100,F23,IF(D3=200,F24,F25))),IF(D3=50,E22,IF(D3=100,E23,IF(D3=200,E24,E25))))) -> 0.603 | E26: Pf=0,5% | F26: Pf=0,5% | G26: Sem fibras
A27: ad | C27: 6 | E27: L = 51 mm | F27: L = 25 mm
J49: n | K49: 1
J50: ng2 | K50: 1
J51: nx1 | K51: =K49 -> 1
J52: nx2 | K52: =K49 -> 1 | S52: ε
K53: 0
A57: p | B57: q | C57: ffibres | D57: qfibres | E57: Vf | F57: Gp | G57: Gf | H57: εspe | I57: εsfe | J57: qp | K57: po | L57: λ | M57: εvp1 | N57: εvp2 | P57: εvpe | Q57: εvp | R57: v(paste) | S57: v(MSW) | T57: εv | U57: εspp | V57: εs | W57: εa(MSW) | Z57: q/p’ | AA57: vcritico (paste) | AC57: M | AE57: λbarra | AF57: εa | AG57: q | AH57: εv
A58: =D3 -> 200 | B58: =$D$4+(A58-$D$3)*$D$5 -> 0 | C58: 0 | D58: 0 | E58: =(1/$C$16)*($C$12/100)/S58 -> 0.009065581 | F58: =3*(1-2*$B$9)*(A59+A58)/(4*(1+$B$9)*$B$4) -> 30453.804 | G58: =$C$18*$C$17*(A58+100)/100/(2*(1+$C$19))*1000 -> 2293200 | H58: 0 | I58: 0 | J58: 0 | K58: =$B$6 -> 200 | L58: 0 | M58: 0 | N58: 0 | P58: 0 | Q58: =M58+N58 -> 0 | R58: =B7 -> 1.603 | S58: =$C$21*(R58-1)+1 -> 1.595055 | T58: 0 | U58: 0 | V58: 0 | W58: 0 | X58: =IF(D$6="E",-B58,B58) -> 0 | Y58: =IF(D$6="E",-J58,J58) -> 0 | Z58: =J58/A58 -> 0 | AA58: =B$8/A58^B$3*((1+K$49)/K$49)^-B$3 -> 1.6776996 | AB58: =(R58-AA58) -> -0.074699588 | AC58: =B$10 -> 1.3825966 | AD58: =IF(K58>K57,(1-A58/K58)/((J58+0.01)/A58/$B$10)^(1+K$49)+A58/K58+0.01,(1-A58/K58)/((J58+0.01)/A58/$D$10)^(1+K$49)+A58/K58+0.01) -> 1.01 | AE58: =IF(ABS(-LN(1-(R58-AA58)/R58)/LN(AD58))<1.2*B$3,1.2*SIGN(-LN(1-(R58-AA58)/R58)/LN(AD58))*B$3,-LN(1-(R58-AA58)/R58)/LN(AD58)) -> -4.5774044 | AF58: =W58 -> 0 | AG58: =IF(D$6="E",-B58,IF(D$6="T",-B58,B58)) -> 0 | AH58: =T58 -> 0
A59: =$A58+($D$7-$D$3)/800 -> 200.25 | B59: =$D$4+(A59-$D$3)*$D$5 -> 0.75 | C59: =2/PI()*(ATAN((B59/A59)^2))/(1+C$12/C$14*10*(100/A58)^0.5) -> 6.4313981e-06 | D59: =3*G58*(I59-I58)+D58 -> 0 | E59: =(1/$C$16)*($C$12/100)/S59 -> 0.0090657423 | F59: =3*(1-2*$B$9)*(A60+A59)/(4*(1+$B$9)*$B$4) -> 30510.775 | G59: =$C$18*$C$17*(A59+100)/100/(2*(1+$C$19))*1000 -> 2295111 | H59: =(B59-B58)/(3*(1-E58)*F58+3*C58*E58*G58)+H58 -> 8.2842566e-06 | I59: =C58*(H59-H58)+I58 -> 0 | J59: =J58+3*(H59-H58)*F58 -> 0.75686139 | K59: =IF(J59<$B$10*(A58^$K$49*(MAX(K$58)-A58))^(1/(1+$K$49))*($K$49^(1/(1+$K$49))),IF(J59/A59>D$10,IF(MAX(J$58)<0.99*$B$10*(A58^$K$49*(K58-A58))^(1/(1+$K$49))*($K$49^(1/(1+$K$49))),MAX(K$58),((J59/$B$10)^(1+$K$49)/(A59^($K$49)*$K$49))+A59),MAX(K$58)),((J59/$B$10)^(1+$K$49)/(A59^($K$49)*$K$49))+A59) -> 200.2515 | L59: =IF(K59<K58,AE58*(MAX(Z$58)-J58/A58)/(J58/A58/D$10-1)/(1+1*(MAX(Z$58)-J58/A58)/(J58/A58/D$10-1))+B$3-B$4,AE58*(J59/A59/B$10)/(C$27+J59/A59/B$10)) -> -0.0020845799 | M59: =M58+L59*2*(K59-K58)/(K58+K59) -> -2.6196753e-06 | N59: =N58+(B$3-B$4)*2*(K59-K58)/(K58+K59) -> 1.3069599e-05 | P59: =P58+$B$4*2*(A59-A58)/(A59+A58) -> 7.4953154e-06 | Q59: =M59+N59 -> 1.0449924e-05 | R59: =R58-(Q59-Q58+P59-P58)*R58 -> 1.6029712 | S59: =$C$21*(R59-1)+1 -> 1.5950266 | T59: =-(S59-S58)/S58+T58 -> 1.7797004e-05 | U59: =(N59-N58)/(K$49/(1+K$49)*(AC59^(1+K$49)-(J59/A59)^(1+K$49))/(J59/A59)^K$49)*K$50+U58 -> 5.1683075e-08 | V59: =IF(D$6="E",-IF(K58=$B$6,-V58+(H59-H58)*(1-E58)+(I59-I58)*E58,-V58+(H59-H58)*(1-E58)+(I59-I58)*E58+(U59-U58)*(1-E58)),IF(K58=$B$6,V58+(H59-H58)*(1-E58)+(I59-I58)*E58,V58+(H59-H58)*(1-E58)+(I59-I58)*E58+(U59-U58)*(1-E58))) -> 8.209155e-06 | W59: =T59/3+V59 -> 1.414149e-05 | X59: =IF(D$6="E",-B59,B59) -> 0.75 | Y59: =IF(D$6="E",-J59,J59) -> 0.75686139 | Z59: =J59/A59 -> 0.0037795825 | AA59: =B$8/A59^B$3*((1+K$49)/K$49)^-B$3 -> 1.6776652 | AB59: =(R59-AA59) -> -0.074693983 | AC59: =IF(R$58>=AA$58,B$10,IF(K59<K58,(Z59-D$10)*(1+1.25*(D$10-Z59)/MAX(Z$58:Z59)*B$10)+D$10,B$10)) -> 1.3825966 | AD59: =IF(K59>K58,(1-A59/K59)/((J59+0.01)/A59/$B$10)^(1+K$49)+A59/K59+0.01,(1-A59/K59)/((J59+0.01)/A59/$D$10)^(1+K$49)+A59/K59+0.01) -> 1.984075 | AE59: =IF(ABS(-LN(1-(R59-AA59)/R59)/LN(AD59))<1.2*B$3,1.2*SIGN(-LN(1-(R59-AA59)/R59)/LN(AD59))*B$3,-LN(1-(R59-AA59)/R59)/LN(AD59)) -> -0.066472978 | AF59: =W59 -> 1.414149e-05 | AG59: =IF(D$6="E",-B59,IF(D$6="T",-B59,B59)) -> 0.75 | AH59: =T59 -> 1.7797004e-05
A60: =IF(J59/A59<=0.99*$B$10,IF(A59>A58,IF(D$5>0,$A59+($D$7-$D$3)/401,IF(J59/A59>1.01*D$10,A59-($D$7-$D$3)/401,A59)),IF(D$5<0,$A59+($D$7-$D$3)/401,IF(J59/A59>1.01*D$10,A59-($D$7-$D$3)/401,A59))),IF(K59>$B$6,IF(B$10>D$10,IF(J59/A59>1.01*D$10,A59-($D$7-$D$3)/401,A59),A59),IF(MAX(J$58:J59)<0.99*$B$10*(A59^$K$49*(K59-A59))^(1/(1+$K$49))*($K$49^(1/(1+$K$49))),$A59+($D$7-$D$3)/401,IF(J59/A59>1.01*$D$10,$A59-($D$7-$D$3)/401,A59)))) -> 200.74875 | B60: =$D$4+(A60-$D$3)*$D$5 -> 2.2462594 | C60: =2/PI()*(ATAN((B60/A60)^2))/(1+C$12/C$14*10*(100/A59)^0.5) -> 5.741401e-05 | D60: =3*G59*(I60-I59)+D59 -> 0.00073049285 | E60: =(1/$C$16)*($C$12/100)/S60 -> 0.0090661126 | F60: =3*(1-2*$B$9)*(A61+A60)/(4*(1+$B$9)*$B$4) -> 30586.672 | G60: =$C$18*$C$17*(A60+100)/100/(2*(1+$C$19))*1000 -> 2298923.5 | H60: =(B60-B59)/(3*(1-E59)*F59+3*C59*E59*G59)+H59 -> 2.4780522e-05 | I60: =C59*(H60-H59)+I59 -> 1.0609405e-10 | J60: =J59+3*(H60-H59)*F59 -> 2.2668029 | K60: =IF(J60<$B$10*(A59^$K$49*(MAX(K$58:K59)-A59))^(1/(1+$K$49))*($K$49^(1/(1+$K$49))),IF(J60/A60>D$10,IF(MAX(J$58:J59)<0.99*$B$10*(A59^$K$49*(K59-A59))^(1/(1+$K$49))*($K$49^(1/(1+$K$49))),MAX(K$58:K59),((J60/$B$10)^(1+$K$49)/(A60^($K$49)*$K$49))+A60),MAX(K$58:K59)),((J60/$B$10)^(1+$K$49)/(A60^($K$49)*$K$49))+A60) -> 200.76214 | L60: =IF(K60<K59,AE59*(MAX(Z$58:Z59)-J59/A59)/(J59/A59/D$10-1)/(1+1*(MAX(Z$58:Z59)-J59/A59)/(J59/A59/D$10-1))+B$3-B$4,AE59*(J60/A60/B$10)/(C$27+J60/A60/B$10)) -> -9.0358401e-05 | M60: =M59+L60*2*(K60-K59)/(K59+K60) -> -2.8497983e-06 | N60: =N59+(B$3-B$4)*2*(K60-K59)/(K59+K60) -> 3.955611e-05 | P60: =P59+$B$4*2*(A60-A59)/(A60+A59) -> 2.2420642e-05 | Q60: =M60+N60 -> 3.6706312e-05 | R60: =R59-(Q60-Q59+P60-P59)*R59 -> 1.6029052 | S60: =$C$21*(R60-1)+1 -> 1.5949614 | T60: =-(S60-S59)/S59+T59 -> 5.8638534e-05 | U60: =(N60-N59)/(K$49/(1+K$49)*(AC60^(1+K$49)-(J60/A60)^(1+K$49))/(J60/A60)^K$49)*K$50+U59 -> 3.646177e-07 | V60: =IF(D$6="E",-IF(K59=$B$6,-V59+(H60-H59)*(1-E59)+(I60-I59)*E59,-V59+(H60-H59)*(1-E59)+(I60-I59)*E59+(U60-U59)*(1-E59)),IF(K59=$B$6,V59+(H60-H59)*(1-E59)+(I60-I59)*E59,V59+(H60-H59)*(1-E59)+(I60-I59)*E59+(U60-U59)*(1-E59))) -> 2.4865968e-05 | W60: =T60/3+V60 -> 4.4412146e-05 | X60: =IF(D$6="E",-B60,B60) -> 2.2462594 | Y60: =IF(D$6="E",-J60,J60) -> 2.2668029 | Z60: =J60/A60 -> 0.011291741 | AA60: =B$8/A60^B$3*((1+K$49)/K$49)^-B$3 -> 1.6775968 | AB60: =(R60-AA60) -> -0.074691556 | AC60: =IF(R$58>=AA$58,B$10,IF(K60<K59,(Z60-D$10)*(1+1.25*(D$10-Z60)/MAX(Z$58:Z60)*B$10)+D$10,B$10)) -> 1.3825966 | AD60: =IF(K60>K59,(1-A60/K60)/((J60+0.01)/A60/$B$10)^(1+K$49)+A60/K60+0.01,(1-A60/K60)/((J60+0.01)/A60/$D$10)^(1+K$49)+A60/K60+0.01) -> 2.0011022 | AE60: =IF(ABS(-LN(1-(R60-AA60)/R60)/LN(AD60))<1.2*B$3,1.2*SIGN(-LN(1-(R60-AA60)/R60)/LN(AD60))*B$3,-LN(1-(R60-AA60)/R60)/LN(AD60)) -> -0.065654685 | AF60: =W60 -> 4.4412146e-05 | AG60: =IF(D$6="E",-B60,IF(D$6="T",-B60,B60)) -> 2.2462594 | AH60: =T60 -> 5.8638534e-05
A61: =IF(J60/A60<=0.99*$B$10,IF(A60>A59,IF(D$5>0,$A60+($D$7-$D$3)/401,IF(J60/A60>1.01*D$10,A60-($D$7-$D$3)/401,A60)),IF(D$5<0,$A60+($D$7-$D$3)/401,IF(J60/A60>1.01*D$10,A60-($D$7-$D$3)/401,A60))),IF(K60>$B$6,IF(B$10>D$10,IF(J60/A60>1.01*D$10,A60-($D$7-$D$3)/401,A60),A60),IF(MAX(J$58:J60)<0.99*$B$10*(A60^$K$49*(K60-A60))^(1/(1+$K$49))*($K$49^(1/(1+$K$49))),$A60+($D$7-$D$3)/401,IF(J60/A60>1.01*$D$10,$A60-($D$7-$D$3)/401,A60)))) -> 201.24751 | B61: =$D$4+(A61-$D$3)*$D$5 -> 3.7425187 | C61: =2/PI()*(ATAN((B61/A61)^2))/(1+C$12/C$14*10*(100/A60)^0.5) -> 0.0001586433 | D61: =3*G60*(I61-I60)+D60 -> 0.007246105 | E61: =(1/$C$16)*($C$12/100)/S61 -> 0.0090664861 | F61: =3*(1-2*$B$9)*(A62+A61)/(4*(1+$B$9)*$B$4) -> 30662.569 | G61: =$C$18*$C$17*(A61+100)/100/(2*(1+$C$19))*1000 -> 2302735.9 | H61: =(B61-B60)/(3*(1-E60)*F60+3*C60*E60*G60)+H60 -> 4.1235282e-05 | I61: =C60*(H61-H60)+I60 -> 1.0508279e-09 | J61: =J60+3*(H61-H60)*F60 -> 3.776692 | K61: =IF(J61<$B$10*(A60^$K$49*(MAX(K$58:K60)-A60))^(1/(1+$K$49))*($K$49^(1/(1+$K$49))),IF(J61/A61>D$10,IF(MAX(J$58:J60)<0.99*$B$10*(A60^$K$49*(K60-A60))^(1/(1+$K$49))*($K$49^(1/(1+$K$49))),MAX(K$58:K60),((J61/$B$10)^(1+$K$49)/(A61^($K$49)*$K$49))+A61),MAX(K$58:K60)),((J61/$B$10)^(1+$K$49)/(A61^($K$49)*$K$49))+A61) -> 201.28458 | L61: =IF(K61<K60,AE60*(MAX(Z$58:Z60)-J60/A60)/(J60/A60/D$10-1)/(1+1*(MAX(Z$58:Z60)-J60/A60)/(J60/A60/D$10-1))+B$3-B$4,AE60*(J61/A61/B$10)/(C$27+J61/A61/B$10)) -> -0.00014818992 | M61: =M60+L61*2*(K61-K60)/(K60+K61) -> -3.2349292e-06 | N61: =N60+(B$3-B$4)*2*(K61-K60)/(K60+K61) -> 6.6584678e-05 | P61: =P60+$B$4*2*(A61-A60)/(A61+A60) -> 3.7308933e-05 | Q61: =M61+N61 -> 6.3349749e-05 | R61: =R60-(Q61-Q60+P61-P60)*R60 -> 1.6028386 | S61: =$C$21*(R61-1)+1 -> 1.5948957 | T61: =-(S61-S60)/S60+T60 -> 9.9827172e-05 | U61: =(N61-N60)/(K$49/(1+K$49)*(AC61^(1+K$49)-(J61/A61)^(1+K$49))/(J61/A61)^K$49)*K$50+U60 -> 8.9540817e-07 | V61: =IF(D$6="E",-IF(K60=$B$6,-V60+(H61-H60)*(1-E60)+(I61-I60)*E60,-V60+(H61-H60)*(1-E60)+(I61-I60)*E60+(U61-U60)*(1-E60)),IF(K60=$B$6,V60+(H61-H60)*(1-E60)+(I61-I60)*E60,V60+(H61-H60)*(1-E60)+(I61-I60)*E60+(U61-U60)*(1-E60))) -> 4.1697535e-05 | W61: =T61/3+V61 -> 7.4973259e-05 | X61: =IF(D$6="E",-B61,B61) -> 3.7425187 | Y61: =IF(D$6="E",-J61,J61) -> 3.776692 | Z61: =J61/A61 -> 0.018766404 | AA61: =B$8/A61^B$3*((1+K$49)/K$49)^-B$3 -> 1.6775285 | AB61: =(R61-AA61) -> -0.074689859 | AC61: =IF(R$58>=AA$58,B$10,IF(K61<K60,(Z61-D$10)*(1+1.25*(D$10-Z61)/MAX(Z$58:Z61)*B$10)+D$10,B$10)) -> 1.3825966 | AD61: =IF(K61>K60,(1-A61/K61)/((J61+0.01)/A61/$B$10)^(1+K$49)+A61/K61+0.01,(1-A61/K61)/((J61+0.01)/A61/$D$10)^(1+K$49)+A61/K61+0.01) -> 2.0043579 | AE61: =IF(ABS(-LN(1-(R61-AA61)/R61)/LN(AD61))<1.2*B$3,1.2*SIGN(-LN(1-(R61-AA61)/R61)/LN(AD61))*B$3,-LN(1-(R61-AA61)/R61)/LN(AD61)) -> -0.065502395 | AF61: =W61 -> 7.4973259e-05 | AG61: =IF(D$6="E",-B61,IF(D$6="T",-B61,B61)) -> 3.7425187 | AH61: =T61 -> 9.9827172e-05
A62: =IF(J61/A61<=0.99*$B$10,IF(A61>A60,IF(D$5>0,$A61+($D$7-$D$3)/401,IF(J61/A61>1.01*D$10,A61-($D$7-$D$3)/401,A61)),IF(D$5<0,$A61+($D$7-$D$3)/401,IF(J61/A61>1.01*D$10,A61-($D$7-$D$3)/401,A61))),IF(K61>$B$6,IF(B$10>D$10,IF(J61/A61>1.01*D$10,A61-($D$7-$D$3)/401,A61),A61),IF(MAX(J$58:J61)<0.99*$B$10*(A61^$K$49*(K61-A61))^(1/(1+$K$49))*($K$49^(1/(1+$K$49))),$A61+($D$7-$D$3)/401,IF(J61/A61>1.01*$D$10,$A61-($D$7-$D$3)/401,A61)))) -> 201.74626 | B62: =$D$4+(A62-$D$3)*$D$5 -> 5.2387781 | C62: =2/PI()*(ATAN((B62/A62)^2))/(1+C$12/C$14*10*(100/A61)^0.5) -> 0.00030942419 | D62: =3*G61*(I62-I61)+D61 -> 0.025233669 | E62: =(1/$C$16)*($C$12/100)/S62 -> 0.0090668625 | F62: =3*(1-2*$B$9)*(A63+A62)/(4*(1+$B$9)*$B$4) -> 30738.466 | G62: =$C$18*$C$17*(A62+100)/100/(2*(1+$C$19))*1000 -> 2306548.4 | H62: =(B62-B61)/(3*(1-E61)*F61+3*C61*E61*G61)+H61 -> 5.7648179e-05 | I62: =C61*(H62-H61)+I61 -> 3.6546239e-09 | J62: =J61+3*(H62-H61)*F61 -> 5.2864767 | K62: =IF(J62<$B$10*(A61^$K$49*(MAX(K$58:K61)-A61))^(1/(1+$K$49))*($K$49^(1/(1+$K$49))),IF(J62/A62>D$10,IF(MAX(J$58:J61)<0.99*$B$10*(A61^$K$49*(K61-A61))^(1/(1+$K$49))*($K$49^(1/(1+$K$49))),MAX(K$58:K61),((J62/$B$10)^(1+$K$49)/(A62^($K$49)*$K$49))+A62),MAX(K$58:K61)),((J62/$B$10)^(1+$K$49)/(A62^($K$49)*$K$49))+A62) -> 201.81873 | L62: =IF(K62<K61,AE61*(MAX(Z$58:Z61)-J61/A61)/(J61/A61/D$10-1)/(1+1*(MAX(Z$58:Z61)-J61/A61)/(J61/A61/D$10-1))+B$3-B$4,AE61*(J62/A62/B$10)/(C$27+J62/A62/B$10)) -> -0.00020625363 | M62: =M61+L62*2*(K62-K61)/(K61+K62) -> -3.7815328e-06 | N62: =N61+(B$3-B$4)*2*(K62-K61)/(K61+K62) -> 9.4146267e-05 | P62: =P61+$B$4*2*(A62-A61)/(A62+A61) -> 5.2160373e-05 | Q62: =M62+N62 -> 9.0364734e-05 | R62: =R61-(Q62-Q61+P62-P61)*R61 -> 1.6027715 | S62: =$C$21*(R62-1)+1 -> 1.5948295 | T62: =-(S62-S61)/S61+T61 -> 0.00014134773 | U62: =(N62-N61)/(K$49/(1+K$49)*(AC62^(1+K$49)-(J62/A62)^(1+K$49))/(J62/A62)^K$49)*K$50+U61 -> 1.6513008e-06 | V62: =IF(D$6="E",-IF(K61=$B$6,-V61+(H62-H61)*(1-E61)+(I62-I61)*E61,-V61+(H62-H61)*(1-E61)+(I62-I61)*E61+(U62-U61)*(1-E61)),IF(K61=$B$6,V61+(H62-H61)*(1-E61)+(I62-I61)*E61,V61+(H62-H61)*(1-E61)+(I62-I61)*E61+(U62-U61)*(1-E61))) -> 5.8710687e-05 | W62: =T62/3+V62 -> 0.0001058266 | X62: =IF(D$6="E",-B62,B62) -> 5.2387781 | Y62: =IF(D$6="E",-J62,J62) -> 5.2864767 | Z62: =J62/A62 -> 0.026203592 | AA62: =B$8/A62^B$3*((1+K$49)/K$49)^-B$3 -> 1.6774604 | AB62: =(R62-AA62) -> -0.074688868 | AC62: =IF(R$58>=AA$58,B$10,IF(K62<K61,(Z62-D$10)*(1+1.25*(D$10-Z62)/MAX(Z$58:Z62)*B$10)+D$10,B$10)) -> 1.3825966 | AD62: =IF(K62>K61,(1-A62/K62)/((J62+0.01)/A62/$B$10)^(1+K$49)+A62/K62+0.01,(1-A62/K62)/((J62+0.01)/A62/$D$10)^(1+K$49)+A62/K62+0.01) -> 2.0055107 | AE62: =IF(ABS(-LN(1-(R62-AA62)/R62)/LN(AD62))<1.2*B$3,1.2*SIGN(-LN(1-(R62-AA62)/R62)/LN(AD62))*B$3,-LN(1-(R62-AA62)/R62)/LN(AD62)) -> -0.065450104 | AF62: =W62 -> 0.0001058266 | AG62: =IF(D$6="E",-B62,IF(D$6="T",-B62,B62)) -> 5.2387781 | AH62: =T62 -> 0.00014134773
A63: =IF(J62/A62<=0.99*$B$10,IF(A62>A61,IF(D$5>0,$A62+($D$7-$D$3)/401,IF(J62/A62>1.01*D$10,A62-($D$7-$D$3)/401,A62)),IF(D$5<0,$A62+($D$7-$D$3)/401,IF(J62/A62>1.01*D$10,A62-($D$7-$D$3)/401,A62))),IF(K62>$B$6,IF(B$10>D$10,IF(J62/A62>1.01*D$10,A62-($D$7-$D$3)/401,A62),A62),IF(MAX(J$58:J62)<0.99*$B$10*(A62^$K$49*(K62-A62))^(1/(1+$K$49))*($K$49^(1/(1+$K$49))),$A62+($D$7-$D$3)/401,IF(J62/A62>1.01*$D$10,$A62-($D$7-$D$3)/401,A62)))) -> 202.24501 | B63: =$D$4+(A63-$D$3)*$D$5 -> 6.7350374 | C63: =2/PI()*(ATAN((B63/A63)^2))/(1+C$12/C$14*10*(100/A62)^0.5) -> 0.00050907235 | D63: =3*G62*(I63-I62)+D62 -> 0.060285032 | E63: =(1/$C$16)*($C$12/100)/S63 -> 0.0090672419 | F63: =3*(1-2*$B$9)*(A64+A63)/(4*(1+$B$9)*$B$4) -> 30814.364 | G63: =$C$18*$C$17*(A63+100)/100/(2*(1+$C$19))*1000 -> 2310360.9 | H63: =(B63-B62)/(3*(1-E62)*F62+3*C62*E62*G62)+H62 -> 7.4018863e-05 | I63: =C62*(H63-H62)+I62 -> 8.7201095e-09 | J63: =J62+3*(H63-H62)*F62 -> 6.7961058 | K63: =IF(J63<$B$10*(A62^$K$49*(MAX(K$58:K62)-A62))^(1/(1+$K$49))*($K$49^(1/(1+$K$49))),IF(J63/A63>D$10,IF(MAX(J$58:J62)<0.99*$B$10*(A62^$K$49*(K62-A62))^(1/(1+$K$49))*($K$49^(1/(1+$K$49))),MAX(K$58:K62),((J63/$B$10)^(1+$K$49)/(A63^($K$49)*$K$49))+A63),MAX(K$58:K62)),((J63/$B$10)^(1+$K$49)/(A63^($K$49)*$K$49))+A63) -> 202.36448 | L63: =IF(K63<K62,AE62*(MAX(Z$58:Z62)-J62/A62)/(J62/A62/D$10-1)/(1+1*(MAX(Z$58:Z62)-J62/A62)/(J62/A62/D$10-1))+B$3-B$4,AE62*(J63/A63/B$10)/(C$27+J63/A63/B$10)) -> -0.00026405247 | M63: =M62+L63*2*(K63-K62)/(K62+K63) -> -4.4946149e-06 | N63: =N62+(B$3-B$4)*2*(K63-K62)/(K62+K63) -> 0.0001222318 | P63: =P62+$B$4*2*(A63-A62)/(A63+A62) -> 6.6975142e-05 | Q63: =M63+N63 -> 0.00011773718 | R63: =R62-(Q63-Q62+P63-P62)*R62 -> 1.6027039 | S63: =$C$21*(R63-1)+1 -> 1.5947628 | T63: =-(S63-S62)/S62+T62 -> 0.00018318641 | U63: =(N63-N62)/(K$49/(1+K$49)*(AC63^(1+K$49)-(J63/A63)^(1+K$49))/(J63/A63)^K$49)*K$50+U62 -> 2.639309e-06 | V63: =IF(D$6="E",-IF(K62=$B$6,-V62+(H63-H62)*(1-E62)+(I63-I62)*E62,-V62+(H63-H62)*(1-E62)+(I63-I62)*E62+(U63-U62)*(1-E62)),IF(K62=$B$6,V62+(H63-H62)*(1-E62)+(I63-I62)*E62,V62+(H63-H62)*(1-E62)+(I63-I62)*E62+(U63-U62)*(1-E62))) -> 7.5912036e-05 | W63: =T63/3+V63 -> 0.00013697417 | X63: =IF(D$6="E",-B63,B63) -> 6.7350374 | Y63: =IF(D$6="E",-J63,J63) -> 6.7961058 | Z63: =J63/A63 -> 0.03360333 | AA63: =B$8/A63^B$3*((1+K$49)/K$49)^-B$3 -> 1.6773925 | AB63: =(R63-AA63) -> -0.074688559 | AC63: =IF(R$58>=AA$58,B$10,IF(K63<K62,(Z63-D$10)*(1+1.25*(D$10-Z63)/MAX(Z$58:Z63)*B$10)+D$10,B$10)) -> 1.3825966 | AD63: =IF(K63>K62,(1-A63/K63)/((J63+0.01)/A63/$B$10)^(1+K$49)+A63/K63+0.01,(1-A63/K63)/((J63+0.01)/A63/$D$10)^(1+K$49)+A63/K63+0.01) -> 2.0058846 | AE63: =IF(ABS(-LN(1-(R63-AA63)/R63)/LN(AD63))<1.2*B$3,1.2*SIGN(-LN(1-(R63-AA63)/R63)/LN(AD63))*B$3,-LN(1-(R63-AA63)/R63)/LN(AD63)) -> -0.065435008 | AF63: =W63 -> 0.00013697417 | AG63: =IF(D$6="E",-B63,IF(D$6="T",-B63,B63)) -> 6.7350374 | AH63: =T63 -> 0.00018318641
A64: =IF(J63/A63<=0.99*$B$10,IF(A63>A62,IF(D$5>0,$A63+($D$7-$D$3)/401,IF(J63/A63>1.01*D$10,A63-($D$7-$D$3)/401,A63)),IF(D$5<0,$A63+($D$7-$D$3)/401,IF(J63/A63>1.01*D$10,A63-($D$7-$D$3)/401,A63))),IF(K63>$B$6,IF(B$10>D$10,IF(J63/A63>1.01*D$10,A63-($D$7-$D$3)/401,A63),A63),IF(MAX(J$58:J63)<0.99*$B$10*(A63^$K$49*(K63-A63))^(1/(1+$K$49))*($K$49^(1/(1+$K$49))),$A63+($D$7-$D$3)/401,IF(J63/A63>1.01*$D$10,$A63-($D$7-$D$3)/401,A63)))) -> 202.74377 | B64: =$D$4+(A64-$D$3)*$D$5 -> 8.2312968 | C64: =2/PI()*(ATAN((B64/A64)^2))/(1+C$12/C$14*10*(100/A63)^0.5) -> 0.00075691288 | D64: =3*G63*(I64-I63)+D63 -> 0.11789759 | E64: =(1/$C$16)*($C$12/100)/S64 -> 0.009067624 | F64: =3*(1-2*$B$9)*(A65+A64)/(4*(1+$B$9)*$B$4) -> 30890.261 | G64: =$C$18*$C$17*(A64+100)/100/(2*(1+$C$19))*1000 -> 2314173.3 | H64: =(B64-B63)/(3*(1-E63)*F63+3*C63*E63*G63)+H63 -> 9.0346998e-05 | I64: =C63*(H64-H63)+I63 -> 1.7032311e-08 | J64: =J63+3*(H64-H63)*F63 -> 8.3055291 | K64: =IF(J64<$B$10*(A63^$K$49*(MAX(K$58:K63)-A63))^(1/(1+$K$49))*($K$49^(1/(1+$K$49))),IF(J64/A64>D$10,IF(MAX(J$58:J63)<0.99*$B$10*(A63^$K$49*(K63-A63))^(1/(1+$K$49))*($K$49^(1/(1+$K$49))),MAX(K$58:K63),((J64/$B$10)^(1+$K$49)/(A64^($K$49)*$K$49))+A64),MAX(K$58:K63)),((J64/$B$10)^(1+$K$49)/(A64^($K$49)*$K$49))+A64) -> 202.92176 | L64: =IF(K64<K63,AE63*(MAX(Z$58:Z63)-J63/A63)/(J63/A63/D$10-1)/(1+1*(MAX(Z$58:Z63)-J63/A63)/(J63/A63/D$10-1))+B$3-B$4,AE63*(J64/A64/B$10)/(C$27+J64/A64/B$10)) -> -0.00032154653 | M64: =M63+L64*2*(K64-K63)/(K63+K64) -> -5.3788786e-06 | N64: =N63+(B$3-B$4)*2*(K64-K63)/(K63+K64) -> 0.00015083214 | P64: =P63+$B$4*2*(A64-A63)/(A64+A63) -> 8.1753421e-05 | Q64: =M64+N64 -> 0.00014545327 | R64: =R63-(Q64-Q63+P64-P63)*R63 -> 1.6026358 | S64: =$C$21*(R64-1)+1 -> 1.5946956 | T64: =-(S64-S63)/S63+T63 -> 0.00022532969 | U64: =(N64-N63)/(K$49/(1+K$49)*(AC64^(1+K$49)-(J64/A64)^(1+K$49))/(J64/A64)^K$49)*K$50+U63 -> 3.8662157e-06 | V64: =IF(D$6="E",-IF(K63=$B$6,-V63+(H64-H63)*(1-E63)+(I64-I63)*E63,-V63+(H64-H63)*(1-E63)+(I64-I63)*E63+(U64-U63)*(1-E63)),IF(K63=$B$6,V63+(H64-H63)*(1-E63)+(I64-I63)*E63,V63+(H64-H63)*(1-E63)+(I64-I63)*E63+(U64-U63)*(1-E63))) -> 9.3307977e-05 | W64: =T64/3+V64 -> 0.00016841787 | X64: =IF(D$6="E",-B64,B64) -> 8.2312968 | Y64: =IF(D$6="E",-J64,J64) -> 8.3055291 | Z64: =J64/A64 -> 0.040965645 | AA64: =B$8/A64^B$3*((1+K$49)/K$49)^-B$3 -> 1.6773247 | AB64: =(R64-AA64) -> -0.07468891 | AC64: =IF(R$58>=AA$58,B$10,IF(K64<K63,(Z64-D$10)*(1+1.25*(D$10-Z64)/MAX(Z$58:Z64)*B$10)+D$10,B$10)) -> 1.3825966 | AD64: =IF(K64>K63,(1-A64/K64)/((J64+0.01)/A64/$B$10)^(1+K$49)+A64/K64+0.01,(1-A64/K64)/((J64+0.01)/A64/$D$10)^(1+K$49)+A64/K64+0.01) -> 2.0058441 | AE64: =IF(ABS(-LN(1-(R64-AA64)/R64)/LN(AD64))<1.2*B$3,1.2*SIGN(-LN(1-(R64-AA64)/R64)/LN(AD64))*B$3,-LN(1-(R64-AA64)/R64)/LN(AD64)) -> -0.065439924 | AF64: =W64 -> 0.00016841787 | AG64: =IF(D$6="E",-B64,IF(D$6="T",-B64,B64)) -> 8.2312968 | AH64: =T64 -> 0.00022532969
A65: =IF(J64/A64<=0.99*$B$10,IF(A64>A63,IF(D$5>0,$A64+($D$7-$D$3)/401,IF(J64/A64>1.01*D$10,A64-($D$7-$D$3)/401,A64)),IF(D$5<0,$A64+($D$7-$D$3)/401,IF(J64/A64>1.01*D$10,A64-($D$7-$D$3)/401,A64))),IF(K64>$B$6,IF(B$10>D$10,IF(J64/A64>1.01*D$10,A64-($D$7-$D$3)/401,A64),A64),IF(MAX(J$58:J64)<0.99*$B$10*(A64^$K$49*(K64-A64))^(1/(1+$K$49))*($K$49^(1/(1+$K$49))),$A64+($D$7-$D$3)/401,IF(J64/A64>1.01*$D$10,$A64-($D$7-$D$3)/401,A64)))) -> 203.24252 | B65: =$D$4+(A65-$D$3)*$D$5 -> 9.7275561 | C65: =2/PI()*(ATAN((B65/A65)^2))/(1+C$12/C$14*10*(100/A64)^0.5) -> 0.0010522801 | D65: =3*G64*(I65-I64)+D64 -> 0.20347473 | E65: =(1/$C$16)*($C$12/100)/S65 -> 0.0090680088 | F65: =3*(1-2*$B$9)*(A66+A65)/(4*(1+$B$9)*$B$4) -> 30966.158 | G65: =$C$18*$C$17*(A65+100)/100/(2*(1+$C$19))*1000 -> 2317985.8 | H65: =(B65-B64)/(3*(1-E64)*F64+3*C64*E64*G64)+H64 -> 0.00010663226 | I65: =C64*(H65-H64)+I64 -> 2.9358836e-08 | J65: =J64+3*(H65-H64)*F64 -> 9.814697 | K65: =IF(J65<$B$10*(A64^$K$49*(MAX(K$58:K64)-A64))^(1/(1+$K$49))*($K$49^(1/(1+$K$49))),IF(J65/A65>D$10,IF(MAX(J$58:J64)<0.99*$B$10*(A64^$K$49*(K64-A64))^(1/(1+$K$49))*($K$49^(1/(1+$K$49))),MAX(K$58:K64),((J65/$B$10)^(1+$K$49)/(A65^($K$49)*$K$49))+A65),MAX(K$58:K64)),((J65/$B$10)^(1+$K$49)/(A65^($K$49)*$K$49))+A65) -> 203.49046 | L65: =IF(K65<K64,AE64*(MAX(Z$58:Z64)-J64/A64)/(J64/A64/D$10-1)/(1+1*(MAX(Z$58:Z64)-J64/A64)/(J64/A64/D$10-1))+B$3-B$4,AE64*(J65/A65/B$10)/(C$27+J65/A65/B$10)) -> -0.00037873685 | M65: =M64+L65*2*(K65-K64)/(K64+K65) -> -6.4388325e-06 | N65: =N64+(B$3-B$4)*2*(K65-K64)/(K64+K65) -> 0.00017993816 | P65: =P64+$B$4*2*(A65-A64)/(A65+A64) -> 9.6495391e-05 | Q65: =M65+N65 -> 0.00017349933 | R65: =R64-(Q65-Q64+P65-P64)*R64 -> 1.6025672 | S65: =$C$21*(R65-1)+1 -> 1.5946279 | T65: =-(S65-S64)/S64+T64 -> 0.00026776419 | U65: =(N65-N64)/(K$49/(1+K$49)*(AC65^(1+K$49)-(J65/A65)^(1+K$49))/(J65/A65)^K$49)*K$50+U64 -> 5.3385764e-06 | V65: =IF(D$6="E",-IF(K64=$B$6,-V64+(H65-H64)*(1-E64)+(I65-I64)*E64,-V64+(H65-H64)*(1-E64)+(I65-I64)*E64+(U65-U64)*(1-E64)),IF(K64=$B$6,V64+(H65-H64)*(1-E64)+(I65-I64)*E64,V64+(H65-H64)*(1-E64)+(I65-I64)*E64+(U65-U64)*(1-E64))) -> 0.00011090469 | W65: =T65/3+V65 -> 0.00020015942 | X65: =IF(D$6="E",-B65,B65) -> 9.7275561 | Y65: =IF(D$6="E",-J65,J65) -> 9.814697 | Z65: =J65/A65 -> 0.04829057 | AA65: =B$8/A65^B$3*((1+K$49)/K$49)^-B$3 -> 1.6772571 | AB65: =(R65-AA65) -> -0.074689898 | AC65: =IF(R$58>=AA$58,B$10,IF(K65<K64,(Z65-D$10)*(1+1.25*(D$10-Z65)/MAX(Z$58:Z65)*B$10)+D$10,B$10)) -> 1.3825966 | AD65: =IF(K65>K64,(1-A65/K65)/((J65+0.01)/A65/$B$10)^(1+K$49)+A65/K65+0.01,(1-A65/K65)/((J65+0.01)/A65/$D$10)^(1+K$49)+A65/K65+0.01) -> 2.0055309 | AE65: =IF(ABS(-LN(1-(R65-AA65)/R65)/LN(AD65))<1.2*B$3,1.2*SIGN(-LN(1-(R65-AA65)/R65)/LN(AD65))*B$3,-LN(1-(R65-AA65)/R65)/LN(AD65)) -> -0.065458192 | AF65: =W65 -> 0.00020015942 | AG65: =IF(D$6="E",-B65,IF(D$6="T",-B65,B65)) -> 9.7275561 | AH65: =T65 -> 0.00026776419
...

Sheet Graficos_resumo

Sheet Exp_res
A1: 50 KPA | B1: 0 | E1: 50 KPA | F1: 0.005 | G1: L25 | I1: 50 KPA | J1: 0.005 | K1: L51 | M1: 100 KPA | N1: 0 | Q1: 100 KPA | R1: 0.5 | S1: L25 | U1: 100 KPA | V1: 0.5 | W1: L51 | Y1: 200 KPA | Z1: 0 | AC1: 200 KPA | AD1: 0.005 | AE1: L25 | AG1: 200 KPA | AH1: 0.005 | AI1: L51 | AK1: 300 KPA | AL1: 0 | AO1: 300 KPA | AP1: 0.5 | AQ1: L25 | AS1: 300 KPA | AT1: 0.5 | AU1: L51 | AZ1: L25 | BC1: L50 | BI1: L25 | BL1: L50 | BR1: L25 | BU1: L50 | CA1: L25 | CD1: L50
A2: def. axial | B2: P.desv. | C2: def vol | E2: 0 | F2: 0 | G2: 0 | I2: 0 | J2: 0 | K2: 0 | M2: def. axial | N2: P.desv. | O2: def vol | Q2: def. axial | R2: P.desv. | S2: def vol | U2: 0 | V2: 0 | W2: 0 | Y2: def. axial | Z2: P.desv. | AA2: def vol | AC2: def. axial | AD2: P.desv. | AE2: def vol | AG2: def. axial | AH2: P.desv. | AI2: def vol | AK2: def. axial | AL2: P.desv. | AM2: def vol | AO2: def. axial | AP2: P.desv. | AQ2: def vol | AS2: def. axial | AT2: P.desv. | AU2: def vol | AW2: σ3 = 50 kPa, dq/dp=3, Pf=0% | AZ2: σ3 = 50 kPa, dq/dp=3, Pf=0,5% | BC2: σ3 = 50 kPa, dq/dp=3, Pf=0,5% | BF2: σ3 = 100 kPa, dq/dp=3, Pf=0% | BI2: σ3 = 100 kPa, dq/dp=3, Pf=0.5% | BL2: σ3 = 100 kPa, dq/dp=3, Pf=0.5% | BO2: σ3 = 200 kPa, dq/dp=3, Pf=0% | BR2: σ3 = 200 kPa, dq/dp=3, Pf=0.5% | BU2: σ3 = 200 kPa, dq/dp=3, Pf=0.5% | BX2: σ3 = 300 kPa, dq/dp=3, Pf=0% | CA2: σ3 = 300 kPa, dq/dp=3, Pf=0.5% | CD2: σ3 = 300 kPa, dq/dp=3, Pf=0.5%
A3: 0 | B3: 0 | C3: 0 | E3: 0.0010069506 | F3: 6.6927708 | G3: 0.0006538073 | I3: 0.00050301811 | J3: 16.351771 | K3: 0 | M3: 0 | N3: 0 | O3: 0 | Q3: 0 | R3: 0 | S3: 0 | U3: 0.0010062275 | V3: 72.857599 | W3: 0.00051714011 | Y3: 0 | Z3: 0 | AA3: 0 | AC3: 0 | AD3: 0 | AE3: 0 | AG3: 0 | AH3: 0 | AI3: 0 | AK3: 0 | AL3: 0 | AM3: 0 | AO3: 0 | AP3: 0 | AQ3: 0 | AS3: 0 | AT3: 0 | AU3: 0 | AW3: 0 | AX3: 0 | AY3: 0 | AZ3: 0 | BA3: 0 | BB3: 0 | BC3: 0 | BD3: 0 | BE3: 0 | BF3: 0 | BG3: 0 | BH3: 0 | BI3: 0 | BJ3: 0 | BK3: 0 | BL3: 0 | BM3: 0 | BN3: 0 | BO3: 0 | BP3: 0 | BQ3: 0 | BR3: 0 | BS3: 0 | BT3: 0 | BU3: 0 | BV3: 0 | BW3: 0 | BX3: 0 | BY3: 0 | BZ3: 0 | CA3: 0 | CB3: 0 | CC3: 0 | CD3: 0 | CE3: 0 | CF3: 0
A4: 0.0010063311 | B4: 12.717643 | C4: -0.00043677157 | I4: 0.0020120724 | J4: 59.876741 | K4: -0.0002885181 | M4: 0 | N4: 26.937904 | O4: -0.00016854857 | Q4: 0.00050371322 | R4: 37.406896 | S4: -0.0003445681 | U4: 0.0035217963 | V4: 148.09056 | W4: 0.001148454 | Y4: 0.0010090038 | Z4: 16.503331 | AA4: 0 | AC4: 0.0035248399 | AD4: 107.67684 | AE4: 0.00011466825 | AG4: 0.0030188581 | AH4: 132.47941 | AI4: 0.00017466954 | AK4: 0.00050325786 | AL4: 37.550336 | AM4: -0.00051788132 | AO4: 0.0015107032 | AP4: 75.378096 | AQ4: 0 | AS4: 0.0045287228 | AT4: 143.53392 | AU4: 0.00028229427 | AW4: 8.4601085e-06 | AX4: 0.148125 | AY4: 5.922076e-06 | AZ4: 1.2652018e-05 | BA4: 0.222 | BB4: 8.8004872e-06 | BC4: 1.623908e-05 | BD4: 0.285 | BE4: 1.1295646e-05 | BF4: 7.8178617e-06 | BG4: 0.27375 | BH4: 5.4725032e-06 | BI4: 1.0366618e-05 | BJ4: 0.36375 | BK4: 7.2107649e-06 | BL4: 1.282279e-05 | BM4: 0.45 | BN4: 8.9191045e-06 | BO4: 9.4580489e-06 | BP4: 0.4875 | BQ4: 1.2362794e-05 | BR4: 1.1932403e-05 | BS4: 0.624375 | BT4: 1.5292699e-05 | BU4: 1.4241106e-05 | BV4: 0.755625 | BW4: 1.7911264e-05 | BX4: 9.1386554e-06 | BY4: 0.703125 | BZ4: 1.2020194e-05 | CA4: 1.1185496e-05 | CB4: 0.87 | CC4: 1.4508553e-05 | CD4: 1.3733018e-05 | CE4: 1.0875 | CF4: 1.7392008e-05
A5: 0.0035221587 | B5: 44.068795 | C5: 0.00032925857 | E5: 0.0030208517 | F5: 37.402546 | G5: 0.00091667827 | I5: 0.0030181087 | J5: 92.372377 | K5: 0.0010869752 | M5: 0 | N5: 28.561902 | O5: 0.00010787108 | Q5: 0.0015111396 | R5: 61.597052 | S5: 0.0012161227 | U5: 0.0055342513 | V5: 210.46483 | W5: 0.0016118653 | Y5: 0.0020180076 | Z5: 26.310334 | AA5: 0.00065370126 | AC5: 0.0055390342 | AD5: 172.60509 | AE5: 0.0009240912 | AG5: 0.0040251442 | AH5: 192.55956 | AI5: 0.00063149756 | AK5: 0.0015097736 | AL5: 141.92544 | AM5: -0.00039009242 | AO5: 0.0025178386 | AP5: 152.38446 | AQ5: 0.0010929291 | AS5: 0.0055351057 | AT5: 237.51769 | AU5: 0.0013778649 | AW5: 2.5313221e-05 | AX5: 0.44363622 | AY5: 1.7719254e-05 | AZ5: 3.7837052e-05 | BA5: 0.66489277 | BB5: 2.631877e-05 | BC5: 4.8544025e-05 | BD5: 0.85357855 | BE5: 3.3766724e-05 | BF5: 2.3393319e-05 | BG5: 0.81988466 | BH5: 1.6375324e-05 | BI5: 3.1010637e-05 | BJ5: 1.0894358 | BK5: 2.1570273e-05 | BL5: 3.8346978e-05 | BM5: 1.3477556 | BN5: 2.6672978e-05 | BO5: 2.9131443e-05 | BP5: 1.4600686 | BQ5: 3.9078438e-05 | BR5: 3.7091715e-05 | BS5: 1.8700109 | BT5: 4.9273279e-05 | BU5: 4.4741566e-05 | BV5: 2.2631063 | BW5: 5.9061202e-05 | BX5: 2.8057821e-05 | BY5: 2.1058681 | BZ5: 3.7718948e-05 | CA5: 3.4555834e-05 | CB5: 2.6056608 | CC5: 4.6090327e-05 | CD5: 4.2992206e-05 | CE5: 3.2570761 | CF5: 5.68798e-05
A6: 0.008553814 | B6: 79.961847 | C6: -0.0014245473 | I6: 0.0040241449 | J6: 124.04815 | K6: 0.0025832435 | M6: 0.0025175004 | N6: 120.76339 | O6: 0.001645034 | U6: 0.0080498201 | V6: 251.43502 | W6: 0.0016655941 | AG6: 0.0075471453 | AH6: 348.86118 | AI6: 0.0013772021 | AO6: 0.0045321095 | AP6: 291.54124 | AQ6: 0.0014437459 | AS6: 0.0075478714 | AT6: 380.14288 | AU6: 0.0013778649 | AW6: 4.2133261e-05 | AX6: 0.73914744 | AY6: 2.9493283e-05 | AZ6: 6.2947191e-05 | BA6: 1.1077855 | BB6: 4.378563e-05 | BC6: 8.0724371e-05 | BD6: 1.4221571 | BE6: 5.6153261e-05 | BF6: 3.8940526e-05 | BG6: 1.3660193 | BH6: 2.7258368e-05 | BI6: 5.1604551e-05 | BJ6: 1.8151216 | BK6: 3.5895212e-05 | BL6: 6.3794076e-05 | BM6: 2.2455112 | BN6: 4.4374036e-05 | BO6: 4.8932549e-05 | BP6: 2.4326372 | BQ6: 6.5953965e-05 | BR6: 6.2459421e-05 | BS6: 3.1156468 | BT6: 8.3511429e-05 | BU6: 7.553689e-05 | BV6: 3.7705876 | BW6: 0.0001005633 | BX6: 4.7101122e-05 | BY6: 3.5086113 | BZ6: 6.3577181e-05 | CA6: 5.8118165e-05 | CB6: 4.3413217 | CC6: 7.7918307e-05 | CD6: 7.2529807e-05 | CE6: 5.4266521 | CF6: 9.6705564e-05
A7: 0.015094966 | B7: 100.49084 | C7: -0.0050867089 | E7: 0.0040278023 | F7: 54.922634 | G7: 0.0015637453 | I7: 0.009054326 | J7: 150.91425 | K7: 0.00016774308 | M7: 0.0045315008 | N7: 165.26325 | O7: 0.001645034 | Q7: 0.0030222793 | R7: 115.49224 | S7: 0.0023173894 | U7: 0.010565389 | V7: 295.56419 | W7: 0.0010947252 | Y7: 0.0045405171 | Z7: 74.524275 | AA7: 0.00091926739 | AC7: 0.010070971 | AD7: 300.54586 | AE7: 0.0016728074 | AG7: 0.010566003 | AH7: 437.7746 | AI7: 0.0019012107 | AK7: 0.003522805 | AL7: 318.39522 | AM7: 0.0001277889 | AO7: 0.0075535159 | AP7: 437.93748 | AQ7: 0.0023680131 | AS7: 0.012076594 | AT7: 595.7069 | AU7: 0.0025272058 | AW7: 5.892036e-05 | AX7: 1.0346587 | AY7: 4.1244252e-05 | AZ7: 8.7981927e-05 | BA7: 1.5506783 | BB7: 6.1201367e-05 | BC7: 0.00011277808 | BD7: 1.9907357 | BE7: 7.8455893e-05 | BF7: 5.4459583e-05 | BG7: 1.912154 | BH7: 3.8121708e-05 | BI7: 7.2148201e-05 | BJ7: 2.5408074 | BK7: 5.0185747e-05 | BL7: 8.9163409e-05 | BM7: 3.1432668 | BN7: 6.2022593e-05 | BO7: 6.8861989e-05 | BP7: 3.4052057 | BQ7: 9.2984803e-05 | BR7: 8.8036775e-05 | BS7: 4.3612827 | BT7: 0.00011799811 | BU7: 0.00010662889 | BV7: 5.2780689 | BW7: 0.00014240204 | BX7: 6.626933e-05 | BY7: 4.9113544 | BZ7: 8.9591136e-05 | CA7: 8.1873913e-05 | CB7: 6.0769825 | CC7: 0.00010998561 | CD7: 0.0001023478 | CE7: 7.5962282 | CF7: 0.00013685602
A8: 0.023145614 | B8: 96.110202 | C8: -0.011093998 | I8: 0.017102616 | J8: 187.03909 | K8: -0.0031066019 | M8: 0.0070490012 | N8: 200.29001 | O8: 0.0010382592 | U8: 0.012577844 | V8: 314.424 | W8: 0.00086637759 | AG8: 0.017106863 | AH8: 535.91834 | AI8: 0.00098083663 | AO8: 0.01107849 | AP8: 535.65471 | AQ8: 0.0027120834 | AS8: 0.014592551 | AT8: 717.65057 | AU8: 0.0025876975 | AW8: 7.5674645e-05 | AX8: 1.3301699 | AY8: 5.2972252e-05 | AZ8: 0.00011294078 | BA8: 1.9935711 | BB8: 7.856628e-05 | BC8: 0.00014470323 | BD8: 2.5593142 | BE8: 0.00010067524 | BF8: 6.9950593e-05 | BG8: 2.4582887 | BH8: 4.8965415e-05 | BI8: 9.2641438e-05 | BJ8: 3.2664931 | BK8: 6.4442044e-05 | BL8: 0.00011445433 | BM8: 4.0410224 | BN8: 7.9618958e-05 | BO8: 8.8920608e-05 | BP8: 4.3777743 | BQ8: 0.00012016718 | BR8: 0.00011382528 | BS8: 5.6069186 | BT8: 0.00015272535 | BU8: 0.00013801962 | BV8: 6.7855502 | BW8: 0.00018456333 | BX8: 8.5563329e-05 | BY8: 6.3140976 | BZ8: 0.00011575752 | CA8: 0.00010582461 | CB8: 7.8126434 | CC8: 0.00014228594 | CD8: 0.00013244828 | CE8: 9.7658042 | CF8: 0.00017731877
A9: 0.037234249 | B9: 104.80607 | C9: -0.017826999 | E9: 0.0060417035 | F9: 69.102361 | G9: 0.0013076146 | I9: 0.024647887 | J9: 191.74728 | K9: -0.0058106204 | M9: 0.011077002 | N9: 218.19923 | O9: -0.00016854857 | Q9: 0.0045334189 | R9: 136.47362 | S9: 0.0028376197 | U9: 0.014590299 | V9: 342.13747 | W9: 0 | Y9: 0.0070630266 | Z9: 257.35871 | AA9: 0.0018385348 | AC9: 0.013595811 | AD9: 374.49613 | AE9: 0.0021921872 | AG9: 0.023144579 | AH9: 598.84461 | AI9: -0.00022841401 | AK9: 0.0055358364 | AL9: 470.49598 | AM9: 0.00090797375 | AO9: 0.014603464 | AP9: 618.74055 | AQ9: 0.0028874918 | AS9: 0.019624466 | AT9: 822.87105 | AU9: 0.0013778649 | AW9: 9.2396246e-05 | AX9: 1.6256811 | AY9: 6.4677372e-05 | AZ9: 0.00013782329 | BA9: 2.4364638 | BB9: 9.5880665e-05 | BC9: 0.000176498 | BD9: 3.1278928 | BE9: 0.00012281194 | BF9: 8.5413657e-05 | BG9: 3.0044233 | BH9: 5.978956e-05 | BI9: 0.00011308412 | BJ9: 3.9921789 | BK9: 7.8664266e-05 | BL9: 0.00013966622 | BM9: 4.9387781 | BN9: 9.716344e-05 | BO9: 0.00010910925 | BP9: 5.3503429 | BQ9: 0.00014749742 | BR9: 0.00013982637 | BS9: 6.8525546 | BT9: 0.00018768534 | BU9: 0.00016971102 | BV9: 8.2930315 | BW9: 0.00022703333 | BX9: 0.00010498399 | BY9: 7.7168407 | BZ9: 0.0001420731 | CA9: 0.00012997172 | CB9: 9.5483042 | CC9: 0.00017481309 | CD9: 0.00016283317 | CE9: 11.93538 | CF9: 0.00021808161
A10: 0.049813388 | B10: 95.959204 | C10: -0.023726775 | I10: 0.031187123 | J10: 204.93992 | K10: -0.0094875488 | M10: 0.014098002 | N10: 219.99964 | O10: -0.00076858146 | U10: 0.020627664 | V10: 391.34909 | W10: -0.0027065904 | AG10: 0.032201153 | AH10: 669.09125 | AI10: -0.0024185013 | AO10: 0.025681954 | AP10: 698.98551 | AQ10: 0 | AS10: 0.023146806 | AT10: 894.4258 | AU10: 0.00051753949 | AW10: 0.00010908529 | AX10: 1.9211923 | AY10: 7.6359702e-05 | AZ10: 0.00016262903 | BA10: 2.8793566 | BB10: 0.00011314481 | BC10: 0.00020816068 | BD10: 3.6964713 | BE10: 0.00014486658 | BF10: 0.00010084887 | BG10: 3.550558 | BH10: 7.0594212e-05 | BI10: 0.0001334761 | BJ10: 4.7178647 | BK10: 9.2852576e-05 | BL10: 0.0001647985 | BM10: 5.8365337 | BN10: 0.00011465634 | BO10: 0.00012942874 | BP10: 6.3229115 | BQ10: 0.00017497194 | BR10: 0.00016604142 | BS10: 8.0981905 | BT10: 0.00022287037 | BU10: 0.00020170482 | BV10: 9.8005128 | BW10: 0.00026979839 | BX10: 0.00012453217 | BY10: 9.1195839 | BZ10: 0.00016853469 | CA10: 0.00015431665 | CB10: 11.283965 | CC10: 0.0002075609 | CD10: 0.00019350429 | CE10: 14.104956 | CF10: 0.00025913246
A11: 0.068430512 | B11: 89.39226 | C11: -0.034054743 | E11: 0.0080556046 | F11: 76.593417 | G11: 0.00026287097 | I11: 0.038732394 | J11: 217.84315 | K11: -0.012822281 | M11: 0.025175004 | N11: 216.02402 | O11: -0.0054879413 | Q11: 0.0065482718 | R11: 166.8461 | S11: 0.0029524757 | U11: 0.026665029 | V11: 427.53241 | W11: -0.007649644 | Y11: 0.010090038 | Z11: 379.04496 | AA11: 0.0021041009 | AC11: 0.016617102 | AD11: 434.39579 | AE11: 0.0016728074 | AG11: 0.037232583 | AH11: 694.80044 | AI11: -0.0040308355 | AK11: 0.0080521257 | AL11: 540.43899 | AM11: 0.0011702773 | AO11: 0.031221199 | AP11: 753.6036 | AQ11: -0.001275084 | AS11: 0.027172337 | AT11: 966.2356 | AU11: -0.0017273721 | AW11: 0.0001257419 | AX11: 2.2167036 | AY11: 8.801933e-05 | AZ11: 0.00018735758 | BA11: 3.3222494 | BB11: 0.00013035902 | BC11: 0.00023968964 | BD11: 4.2650499 | BE11: 0.00016683978 | BF11: 0.00011625635 | BG11: 4.0966926 | BH11: 8.1379443e-05 | BI11: 0.00015381726 | BJ11: 5.4435505 | BK11: 0.00010700713 | BL11: 0.0001898506 | BM11: 6.7342893 | BN11: 0.00013209797 | BO11: 0.00014987987 | BP11: 7.29548 | BQ11: 0.00020258715 | BR11: 0.00019247172 | BS11: 9.3438264 | BT11: 0.0002582728 | BU11: 0.00023400262 | BV11: 11.307994 | BW11: 0.00031284497 | BX11: 0.00014420869 | BY11: 10.522327 | BZ11: 0.00019513913 | CA11: 0.00017886075 | CB11: 13.019626 | CC11: 0.00024052328 | CD11: 0.00022446328 | CE11: 16.274532 | CF11: 0.00030045935
A12: 0.076481161 | B12: 80.593084 | C12: -0.037340609 | I12: 0.045774648 | J12: 214.42602 | K12: -0.016673662 | M12: 0.034238006 | N12: 222.55429 | O12: -0.0083937186 | U12: 0.034714849 | V12: 452.66057 | W12: -0.010584582 | AG12: 0.045786015 | AH12: 719.67228 | AI12: -0.0068457022 | AO12: 0.040285418 | AP12: 780.0552 | AQ12: -0.0040478857 | AS12: 0.029688294 | AT12: 1000.8748 | AU12: -0.0027086807 | AW12: 0.00014236621 | AX12: 2.5122148 | AY12: 9.9656344e-05 | AZ12: 0.00021200857 | BA12: 3.7651421 | BB12: 0.00014752357 | BC12: 0.00027108338 | BD12: 4.8336284 | BE12: 0.00018873214 | BF12: 0.00013163617 | BG12: 4.6428273 | BH12: 9.2145322e-05 | BI12: 0.00017410749 | BJ12: 6.1692363 | BK12: 0.0001211281 | BL12: 0.000214822 | BM12: 7.6320449 | BN12: 0.00014948862 | BO12: 0.00017046341 | BP12: 8.2680486 | BQ12: 0.00023033952 | BR12: 0.00021911849 | BS12: 10.589462 | BT12: 0.00029388506 | BU12: 0.00026660585 | BV12: 12.815475 | BW12: 0.00035615969 | BX12: 0.00016401433 | BY12: 11.92507 | BZ12: 0.00022188328 | CA12: 0.00020360527 | CB12: 14.755287 | CC12: 0.00027369416 | CD12: 0.00025571162 | CE12: 18.444108 | CF12: 0.00034205042
A13: 0.089563465 | B13: 70.43309 | C13: -0.040176265 | E13: 0.015104259 | F13: 102.95844 | G13: -0.001172809 | I13: 0.052313883 | J13: 189.68485 | K13: -0.018512127 | M13: 0.043301007 | N13: 232.05483 | O13: -0.013382756 | Q13: 0.0095705511 | R13: 214.66777 | S13: 0.0036483682 | U13: 0.040752214 | V13: 456.41238 | W13: -0.013116554 | Y13: 0.012612547 | Z13: 428.07314 | AA13: 0.001579778 | AC13: 0.022156137 | AD13: 476.93299 | AE13: 0.00011466825 | AG13: 0.053836303 | AH13: 750.50963 | AI13: -0.010412992 | AK13: 0.010568415 | AL13: 580.46643 | AM13: 0.00090797375 | AO13: 0.053881747 | AP13: 783.02533 | AQ13: -0.0075695463 | AS13: 0.033210634 | AT13: 1047.1428 | AU13: -0.0045503147 | AW13: 0.00015895833 | AX13: 2.807726 | AY13: 0.00011127083 | AZ13: 0.00023658163 | BA13: 4.2080349 | BB13: 0.00016463875 | BC13: 0.00030234049 | BD13: 5.402207 | BE13: 0.00021054425 | BF13: 0.00014698846 | BG13: 5.188962 | BH13: 0.00010289192 | BI13: 0.00019434665 | BJ13: 6.8949221 | BK13: 0.00013521564 | BL13: 0.00023971219 | BM13: 8.5298005 | BN13: 0.00016682859 | BO13: 0.0001911801 | BP13: 9.2406172 | BQ13: 0.00025822555 | BR13: 0.00024598284 | BS13: 11.835098 | BT13: 0.00032969966 | BU13: 0.00029951574 | BV13: 14.322957 | BW13: 0.00039972929 | BX13: 0.00018394989 | BY13: 13.327813 | BZ13: 0.00024876405 | CA13: 0.00022855142 | CB13: 16.490948 | CC13: 0.00030706753 | CD13: 0.00028725068 | CE13: 20.613685 | CF13: 0.00038389394
A14: 0.098117279 | B14: 57.542406 | C14: -0.040834782 | I14: 0.058853119 | J14: 207.29899 | K14: -0.020182848 | M14: 0.054378009 | N14: 228.67329 | O14: -0.018479665 | U14: 0.046286465 | V14: 464.0974 | W14: -0.015876873 | AG14: 0.064905449 | AH14: 753.78891 | AI14: -0.014215413 | AO14: 0.060931695 | AP14: 800.67967 | AQ14: -0.0094180808 | AS14: 0.041764888 | AT14: 1104.9984 | AU14: -0.008697352 | AW14: 0.0001755184 | AX14: 3.1032372 | AY14: 0.00012286288 | AZ14: 0.00026107642 | BA14: 4.6509277 | BB14: 0.00018170484 | BC14: 0.00033345963 | BD14: 5.9707855 | BE14: 0.0002322767 | BF14: 0.00016231329 | BG14: 5.7350966 | BH14: 0.0001136193 | BI14: 0.00021453466 | BJ14: 7.6206079 | BK14: 0.0001492699 | BL14: 0.0002645207 | BM14: 9.4275561 | BN14: 0.00018411818 | BO14: 0.00021203065 | BP14: 10.213186 | BQ14: 0.00028624176 | BR14: 0.00027306582 | BS14: 13.080734 | BT14: 0.00036570915 | BU14: 0.00033273339 | BV14: 15.830438 | BW14: 0.00044354068 | BX14: 0.00020401609 | BY14: 14.730556 | BZ14: 0.00027577833 | CA14: 0.00025370033 | CB14: 18.226608 | CC14: 0.00034063742 | CD14: 0.00031908165 | CE14: 22.783261 | CF14: 0.00042597828
A15: 0.10717426 | B15: 74.855751 | C15: -0.041271553 | E15: 0.022656388 | F15: 101.76222 | G15: -0.0059921102 | I15: 0.065895372 | J15: 206.5807 | K15: -0.021618728 | M15: 0.067469012 | N15: 213.18145 | O15: -0.021223635 | Q15: 0.014607683 | R15: 227.39464 | S15: 0.0021417272 | U15: 0.051820717 | V15: 458.37562 | W15: -0.018583463 | Y15: 0.014630555 | Z15: 468.41826 | AA15: 0.0011848335 | AC15: 0.028198719 | AD15: 512.68584 | AE15: -0.0017335142 | AG15: 0.072955738 | AH15: 737.52858 | AI15: -0.016398782 | AK15: 0.013084704 | AL15: 631.16261 | AM15: 0.00090797375 | AO15: 0.067478075 | AP15: 788.18984 | AQ15: -0.011030489 | AS15: 0.049815951 | AT15: 1140.5747 | AU15: -0.011574065 | AW15: 0.00019204654 | AX15: 3.3987484 | AY15: 0.00013443257 | AZ15: 0.00028549262 | BA15: 5.0938204 | BB15: 0.00019872212 | BC15: 0.0003644396 | BD15: 6.5393641 | BE15: 0.00025393006 | BF15: 0.00017761077 | BG15: 6.2812313 | BH15: 0.00012432754 | BI15: 0.0002346714 | BJ15: 8.3462936 | BK15: 0.00016329105 | BL15: 0.00028924708 | BM15: 10.325312 | BN15: 0.00020135767 | BO15: 0.00023301575 | BP15: 11.185754 | BQ15: 0.0003143847 | BR15: 0.0003003684 | BS15: 14.32637 | BT15: 0.00040190618 | BU15: 0.00036625972 | BV15: 17.337919 | BW15: 0.0004875809 | BX15: 0.00022421366 | BY15: 16.1333 | BZ15: 0.00030292307 | CA15: 0.00027905306 | CB15: 19.962269 | CC15: 0.0003743979 | CD15: 0.00035120558 | CE15: 24.952837 | CF15: 0.00046829192
A16: 0.11774073 | B16: 68.28634 | C16: -0.042198853 | I16: 0.073943662 | J16: 197.00162 | K16: -0.023343127 | M16: 0.080056514 | N16: 200.66629 | O16: -0.023852993 | U16: 0.057858082 | V16: 453.99618 | W16: -0.021860923 | AG16: 0.081509169 | AH16: 736.83691 | AI16: -0.017896909 | AO16: 0.07301732 | AP16: 781.45446 | AQ16: -0.012190882 | AS16: 0.05635744 | AT16: 1145.3332 | AU16: -0.013879468 | AW16: 0.00020854286 | AX16: 3.6942597 | AY16: 0.00014598 | AZ16: 0.00030982993 | BA16: 5.5367132 | BB16: 0.00021569088 | BC16: 0.00039527926 | BD16: 7.1079426 | BE16: 0.00027550492 | BF16: 0.000192881 | BG16: 6.827366 | BH16: 0.0001350167 | BI16: 0.0002547568 | BJ16: 9.0719794 | BK16: 0.00017727923 | BL16: 0.0003138909 | BM16: 11.223067 | BN16: 0.00021854736 | BO16: 0.00025413605 | BP16: 12.158323 | BQ16: 0.00034265097 | BR16: 0.00032789148 | BS16: 15.572006 | BT16: 0.00043828344 | BU16: 0.00040009553 | BV16: 18.845401 | BW16: 0.00053183711 | BX16: 0.00024454329 | BY16: 17.536043 | BZ16: 0.00033019523 | CA16: 0.00030461062 | CB16: 21.69793 | CC16: 0.00040834309 | CD16: 0.00038362342 | CE16: 27.122413 | CF16: 0.00051082348
A17: 0.12730088 | B17: 59.421285 | C17: -0.043347898 | E17: 0.029705042 | F17: 110.2431 | G17: -0.0084657934 | I17: 0.081991952 | J17: 206.46723 | K17: -0.024664943 | M17: 0.093147516 | N17: 211.50164 | O17: -0.026482351 | Q17: 0.019141102 | R17: 253.13994 | S17: 0.0010404606 | U17: 0.068423471 | V17: 430.87062 | W17: -0.026924866 | Y17: 0.017657566 | Z17: 474.18715 | AA17: 0.00039494451 | AC17: 0.023163234 | AD17: 486.7553 | AE17: -0.00011466825 | AG17: 0.089559457 | AH17: 712.45815 | AI17: -0.019509244 | AK17: 0.015097736 | AL17: 641.04332 | AM17: -0.00039009242 | AO17: 0.080067269 | AP17: 780.78945 | AQ17: -0.014039417 | AS17: 0.064911694 | AT17: 1152.9472 | AU17: -0.016588149 | AW17: 0.0002250075 | AX17: 3.9897709 | AY17: 0.00015750525 | AZ17: 0.00033408809 | BA17: 5.979606 | BB17: 0.00023261138 | BC17: 0.00042597757 | BD17: 7.6765212 | BE17: 0.00029700183 | BF17: 0.00020812407 | BG17: 7.3735006 | BH17: 0.00014568685 | BI17: 0.00027479075 | BJ17: 9.7976652 | BK17: 0.00019123461 | BL17: 0.00033845177 | BM17: 12.120823 | BN17: 0.00023568754 | BO17: 0.0002753922 | BP17: 13.130892 | BQ17: 0.00037103717 | BR17: 0.00035563588 | BS17: 16.817642 | BT17: 0.0004748337 | BU17: 0.00043424142 | BV17: 20.352882 | BW17: 0.00057629665 | BX17: 0.00026500565 | BY17: 18.938786 | BZ17: 0.0003575918 | CA17: 0.00033037394 | CB17: 23.433591 | CC17: 0.00044246715 | CD17: 0.00041633594 | CE17: 29.291989 | CF17: 0.00055356168
A18: 0.14138951 | B18: 75.498991 | C18: -0.044113928 | I18: 0.09054326 | J18: 198.8598 | K18: -0.025986758 | M18: 0.10724552 | N18: 185.34296 | O18: -0.029610612 | U18: 0.080498201 | V18: 403.09183 | W18: -0.030430673 | AG18: 0.098112889 | AH18: 700.28154 | AI18: -0.020832701 | AO18: 0.086613649 | AP18: 761.0872 | AQ18: -0.015658571 | AS18: 0.071453182 | AT18: 1132.1932 | AU18: -0.018544045 | AW18: 0.00024144058 | AX18: 4.2852821 | AY18: 0.0001690084 | AZ18: 0.00035826683 | BA18: 6.4224988 | BB18: 0.0002494839 | BC18: 0.00045653356 | BD18: 8.2450998 | BE18: 0.00031842136 | BF18: 0.00022334008 | BG18: 7.9196353 | BH18: 0.00015633806 | BI18: 0.00029477319 | BJ18: 10.523351 | BK18: 0.00020515733 | BL18: 0.00036292933 | BM18: 13.018579 | BN18: 0.00025277848 | BO18: 0.0002967848 | BP18: 14.10346 | BQ18: 0.00039953996 | BR18: 0.00038360234 | BS18: 18.063278 | BT18: 0.00051154979 | BU18: 0.00046869788 | BV18: 21.860363 | BW18: 0.00062094701 | BX18: 0.00028560138 | BY18: 20.341529 | BZ18: 0.00038510977 | CA18: 0.0003563439 | CB18: 25.169252 | CC18: 0.00047676429 | CD18: 0.00044934379 | CE18: 31.461565 | CF18: 0.00059649538
A19: 0.15145283 | B19: 70.346772 | C19: -0.045101704 | E19: 0.035746746 | F19: 110.13065 | G19: -0.013028964 | I19: 0.099597586 | J19: 197.87425 | K19: -0.027362252 | M19: 0.12738552 | N19: 180.29277 | O19: -0.032138841 | Q19: 0.024178234 | R19: 267.52223 | S19: -0.00058103641 | U19: 0.093579158 | V19: 406.69645 | W19: -0.033076819 | Y19: 0.020180076 | Z19: 480.98492 | AA19: -0.00066051064 | AC19: 0.029205816 | AD19: 522.26334 | AE19: -0.0016188459 | AG19: 0.10716946 | AH19: 682.24129 | AI19: -0.022445035 | AK19: 0.017614025 | AL19: 661.0281 | AM19: -0.00051788132 | AO19: 0.097188571 | AP19: 780.48556 | AQ19: -0.017797204 | AS19: 0.079504245 | AT19: 1084.4683 | AU19: -0.022859114 | AW19: 0.0002578422 | AX19: 4.5807933 | AY19: 0.00018048954 | AZ19: 0.00038236593 | BA19: 6.8653915 | BB19: 0.00026630872 | BC19: 0.00048694638 | BD19: 8.8136783 | BE19: 0.00033976406 | BF19: 0.00023852913 | BG19: 8.46577 | BH19: 0.00016697039 | BI19: 0.00031470404 | BJ19: 11.249037 | BK19: 0.00021904756 | BL19: 0.00038732321 | BM19: 13.916334 | BN19: 0.00026982047 | BO19: 0.00031831442 | BP19: 15.076029 | BQ19: 0.00042815599 | BR19: 0.00041179154 | BS19: 19.308914 | BT19: 0.00054842463 | BU19: 0.00050346525 | BV19: 23.367844 | BW19: 0.00066577581 | BX19: 0.00030633112 | BY19: 21.744272 | BZ19: 0.00041274618 | CA19: 0.00038252131 | CB19: 26.904913 | CC19: 0.00051122876 | CD19: 0.00048264752 | CE19: 33.631141 | CF19: 0.00063961355
A20: 0.16906362 | B20: 65.434199 | C20: -0.047016779 | I20: 0.10764588 | J20: 190.60103 | K20: -0.029261103 | M20: 0.13846252 | N20: 193.83608 | O20: -0.033291713 | U20: 0.10666012 | V20: 380.49812 | W20: -0.036240104 | AG20: 0.11622604 | AH20: 685.22355 | AI20: -0.023479617 | AO20: 0.10977776 | AP20: 763.37145 | AQ20: -0.020860104 | AS20: 0.086548925 | AT20: 1013.2001 | AU20: -0.025971073 | AW20: 0.00027421251 | AX20: 4.8763046 | AY20: 0.00019194876 | AZ20: 0.00040638517 | BA20: 7.3082843 | BB20: 0.0002830861 | BC20: 0.00051721522 | BD20: 9.3822569 | BE20: 0.00036103049 | BF20: 0.00025369131 | BG20: 9.0119046 | BH20: 0.00017758392 | BI20: 0.00033458324 | BJ20: 11.974723 | BK20: 0.00023290543 | BL20: 0.0004116331 | BM20: 14.81409 | BN20: 0.00028681379 | BO20: 0.00033998164 | BP20: 16.048597 | BQ20: 0.00045688198 | BR20: 0.00044020407 | BS20: 20.55455 | BT20: 0.00058545119 | BU20: 0.00053854372 | BV20: 24.875326 | BW20: 0.00071077083 | BX20: 0.00032719544 | BY20: 23.147015 | BZ20: 0.00044049809 | CA20: 0.00040890693 | CB20: 28.640574 | CC20: 0.00054585485 | CD20: 0.00051624752 | CE20: 35.800717 | CF20: 0.0006829053
A21: 0.18214592 | B21: 68.843488 | C21: -0.047997835 | E21: 0.04380235 | F21: 88.024226 | G21: -0.017201198 | I21: 0.11619718 | J21: 199.24699 | K21: -0.030985502 | M21: 0.15960953 | N21: 183.12587 | O21: -0.034876069 | Q21: 0.036267352 | R21: 275.87907 | S21: -0.0048036848 | U21: 0.12024419 | V21: 377.44056 | W21: -0.039349661 | Y21: 0.022702585 | Z21: 498.66872 | AA21: -0.0014503997 | AC21: 0.025177428 | AD21: 499.29634 | AE21: -0.00063404798 | AG21: 0.1262889 | AH21: 684.56598 | AI21: -0.024399991 | AK21: 0.020130314 | AL21: 675.77094 | AM21: -0.0015603697 | AO21: 0.11582058 | AP21: 742.03998 | AQ21: -0.021899062 | AS21: 0.097619136 | AT21: 993.02637 | AU21: -0.027120414 | AW21: 0.00029055161 | AX21: 5.1718158 | AY21: 0.00020338612 | AZ21: 0.00043032435 | BA21: 7.7511771 | BB21: 0.0002998163 | BC21: 0.0005473394 | BD21: 9.9508354 | BE21: 0.00038222118 | BF21: 0.00026882672 | BG21: 9.5580393 | BH21: 0.00018817871 | BI21: 0.00035441072 | BJ21: 12.700408 | BK21: 0.00024673111 | BL21: 0.00043585871 | BM21: 15.711845 | BN21: 0.00030375872 | BO21: 0.00036178698 | BP21: 17.021166 | BQ21: 0.00048571465 | BR21: 0.00046884049 | BS21: 21.800185 | BT21: 0.0006226225 | BU21: 0.00057393335 | BV21: 26.382807 | BW21: 0.00075592004 | BX21: 0.00034819493 | BY21: 24.549758 | BZ21: 0.00046836257 | CA21: 0.00043550146 | CB21: 30.376234 | CC21: 0.00058063693 | CD21: 0.00055014408 | CE21: 37.970293 | CF21: 0.00072635986
A22: 0.19724089 | B22: 66.136854 | C22: -0.048710109 | I22: 0.12525151 | J22: 192.34007 | K22: -0.032595836 | M22: 0.17672853 | N22: 174.60969 | O22: -0.035644651 | U22: 0.13483449 | V22: 373.98441 | W22: -0.042741294 | AG22: 0.13635176 | AH22: 679.38433 | AI22: -0.025898118 | AO22: 0.12538836 | AP22: 764.94968 | AQ22: -0.023282089 | AS22: 0.10516701 | AT22: 973.54285 | AU22: -0.027523691 | AW22: 0.00030685962 | AX22: 5.467327 | AY22: 0.00021480173 | AZ22: 0.00045418329 | BA22: 8.1940698 | BB22: 0.0003164996 | BC22: 0.00057731827 | BD22: 10.519414 | BE22: 0.00040333667 | BF22: 0.00028393545 | BG22: 10.104174 | BH22: 0.00019875482 | BI22: 0.00037418644 | BJ22: 13.426094 | BK22: 0.00026052473 | BL22: 0.00045999975 | BM22: 16.609601 | BN22: 0.00032065553 | BO22: 0.00038373096 | BP22: 17.993734 | BQ22: 0.00051465075 | BR22: 0.00049770126 | BS22: 23.045821 | BT22: 0.0006599317 | BU22: 0.00060963409 | BV22: 27.890288 | BW22: 0.00080121152 | BX22: 0.00036933015 | BY22: 25.952502 | BZ22: 0.00049633671 | CA22: 0.00046230552 | CB22: 32.111895 | CC22: 0.00061556938 | CD22: 0.00058433736 | CE22: 40.139869 | CF22: 0.00076996659
E23: 0.051354479 | F23: 92.224151 | G23: -0.018893009 | I23: 0.13531187 | J23: 194.68671 | K23: -0.034608753 | M23: 0.18730203 | N23: 175.16789 | O23: -0.036467168 | Q23: 0.044326763 | R23: 280.41566 | S23: -0.0061954697 | U23: 0.1534497 | V23: 359.59693 | W23: -0.044695681 | Y23: 0.028756608 | Z23: 500.80523 | AA23: -0.0038200667 | AC23: 0.032227108 | AD23: 544.91445 | AE23: -0.0025429371 | AG23: 0.14641462 | AH23: 663.6718 | AI23: -0.027046906 | AK23: 0.025162893 | AL23: 703.51453 | AM23: -0.0028584359 | AO23: 0.13445258 | AP23: 752.79833 | AQ23: -0.024496455 | AS23: 0.11321807 | AT23: 966.37478 | AU23: -0.028444508 | AW23: 0.00032313666 | AX23: 5.7628382 | AY23: 0.00022619566 | AZ23: 0.00047796185 | BA23: 8.6369626 | BB23: 0.00033313626 | BC23: 0.00060715128 | BD23: 11.087993 | BE23: 0.0004243775 | BF23: 0.0002990176 | BG23: 10.650309 | BH23: 0.00020931232 | BI23: 0.00039391035 | BJ23: 14.15178 | BK23: 0.00027428646 | BL23: 0.00048405598 | BM23: 17.507357 | BN23: 0.00033750449 | BO23: 0.00040581406 | BP23: 18.966303 | BQ23: 0.00054368708 | BR23: 0.00052678678 | BS23: 24.291457 | BT23: 0.00069737195 | BU23: 0.00064564573 | BV23: 29.39777 | BW23: 0.00084663355 | BX23: 0.00039060161 | BY23: 27.355245 | BZ23: 0.00052441764 | CA23: 0.00048931971 | CB23: 33.847556 | CC23: 0.00065064663 | CD23: 0.00061882742 | CE23: 42.309445 | CF23: 0.00081371498
I24: 0.14486922 | J24: 192.41755 | K24: -0.035239467 | M24: 0.20140003 | N24: 181.91179 | O24: -0.036966072 | U24: 0.16904622 | V24: 377.47106 | W24: -0.045790406 | AG24: 0.15345862 | AH24: 671.69043 | AI24: -0.027792611 | AO24: 0.14704178 | AP24: 724.82044 | AQ24: -0.026176328 | AS24: 0.12076594 | AT24: 938.51263 | AU24: -0.029251063 | AW24: 0.00033938285 | AX24: 6.0583494 | AY24: 0.000237568 | AZ24: 0.00050165989 | BA24: 9.0798554 | BB24: 0.00034972653 | BC24: 0.00063683797 | BD24: 11.656571 | BE24: 0.00044534419 | BF24: 0.00031407325 | BG24: 11.196443 | BH24: 0.00021985127 | BI24: 0.0004135824 | BJ24: 14.877466 | BK24: 0.00028801643 | BL24: 0.00050802716 | BM24: 18.405112 | BN24: 0.00035430588 | BO24: 0.00042803675 | BP24: 19.938872 | BQ24: 0.00057282044 | BR24: 0.0005560974 | BS24: 25.537093 | BT24: 0.00073493653 | BU24: 0.00068196797 | BV24: 30.905251 | BW24: 0.00089217456 | BX24: 0.00041200983 | BY24: 28.757988 | BZ24: 0.0005526025 | CA24: 0.00051654456 | CB24: 35.583217 | CC24: 0.00068586319 | CD24: 0.0006536142 | CE24: 44.479021 | CF24: 0.00085759467
A25: 0 | B25: 0 | C25: 0 | E25: 0.057899658 | F25: 94.588015 | G25: -0.020719625 | I25: 0.15442656 | J25: 190.06621 | K25: -0.036333152 | Q25: 0.052889888 | R25: 274.33463 | S25: -0.0078169666 | U25: 0.18514586 | V25: 374.24252 | W25: -0.046824686 | Y25: 0.032288121 | Z25: 516.72492 | AA25: -0.0046099557 | AC25: 0.04179453 | AD25: 569.67365 | AE25: -0.0056592155 | AG25: 0.16754663 | AH25: 654.53537 | AI25: -0.029230275 | AK25: 0.02818244 | AL25: 716.98142 | AM25: -0.0035108318 | AO25: 0.15560243 | AP25: 736.16176 | AQ25: -0.026985905 | AS25: 0.12982339 | AT25: 939.77815 | AU25: -0.02913008 | AW25: 0.00035559831 | AX25: 6.3538607 | AY25: 0.00024891882 | AZ25: 0.00052527727 | BA25: 9.5227481 | BB25: 0.00036627067 | BC25: 0.00066637792 | BD25: 12.22515 | BE25: 0.00046623726 | BF25: 0.0003291025 | BG25: 11.742578 | BH25: 0.00023037175 | BI25: 0.00043320257 | BJ25: 15.603151 | BK25: 0.00030171479 | BL25: 0.00053191309 | BM25: 19.302868 | BN25: 0.00037105996 | BO25: 0.00045039947 | BP25: 20.91144 | BQ25: 0.00060204767 | BR25: 0.00058563339 | BS25: 26.782729 | BT25: 0.00077261876 | BU25: 0.00071860036 | BV25: 32.412732 | BW25: 0.00093782313 | BX25: 0.0004335553 | BY25: 30.160731 | BZ25: 0.00058088845 | CA25: 0.00054398053 | CB25: 37.318878 | CC25: 0.00072121359 | CD25: 0.00068869753 | CE25: 46.648597 | CF25: 0.00090159542
A26: 0.0010063828 | B26: 13.366853 | C26: 0.00010754067 | I26: 0.16448692 | J26: 192.76621 | K26: -0.036963866 | M26: 0 | N26: 0 | O26: 0 | U26: 0.20023927 | V26: 352.90683 | W26: -0.047630619 | AG26: 0.17911891 | AH26: 650.42076 | AI26: -0.030842609 | AO26: 0.16315594 | AP26: 728.77149 | AQ26: -0.027734764 | AS26: 0.13787445 | AT26: 968.74683 | AU26: -0.029419095 | AW26: 0.00037178315 | AX26: 6.6493719 | AY26: 0.0002602482 | AZ26: 0.0005488139 | BA26: 9.9656409 | BB26: 0.00038276894 | BC26: 0.0006957708 | BD26: 12.793728 | BE26: 0.00048705723 | BF26: 0.00034410545 | BG26: 12.288713 | BH26: 0.00024087381 | BI26: 0.00045277081 | BJ26: 16.328837 | BK26: 0.00031538169 | BL26: 0.00055571359 | BM26: 20.200623 | BN26: 0.000387767 | BO26: 0.00047290264 | BP26: 21.884009 | BQ26: 0.00063136564 | BR26: 0.00061539499 | BS26: 28.028365 | BT26: 0.00081041204 | BU26: 0.00075554237 | BV26: 33.920214 | BW26: 0.00098356802 | BX26: 0.00045523848 | BY26: 31.563474 | BZ26: 0.00060927269 | CA26: 0.00057162806 | CB26: 39.054539 | CC26: 0.00075669242 | CD26: 0.00072407714 | CE26: 48.818173 | CF26: 0.00094570713
A27: 0.00352234 | B27: 26.896328 | C27: 0.0010418003 | E27: 0.064948312 | F27: 90.743861 | G27: -0.021892434 | I27: 0.17454728 | J27: 190.00496 | K27: -0.037769032 | M27: 0.0025195141 | N27: 70.896474 | O27: 0.0013267198 | Q27: 0.060445586 | R27: 276.98527 | S27: -0.0089722832 | U27: 0.2158358 | V27: 355.0648 | W27: -0.049182039 | Y27: 0.03985565 | Z27: 496.0875 | AA27: -0.0082938347 | AC27: 0.050354856 | AD27: 578.63873 | AE27: -0.010111042 | AG27: 0.1906912 | AH27: 664.0199 | AI27: -0.032340737 | AK27: 0.034724792 | AL27: 732.78754 | AM27: -0.0057235975 | AO27: 0.17171659 | AP27: 701.79927 | AQ27: -0.02917851 | AS27: 0.1469319 | AT27: 955.98719 | AU27: -0.030111389 | AW27: 0.00038793748 | AX27: 6.9448831 | AY27: 0.00027155624 | AZ27: 0.00057226969 | BA27: 10.408534 | BB27: 0.00039922159 | BC27: 0.00072501634 | BD27: 13.362307 | BE27: 0.0005078046 | BF27: 0.00035908218 | BG27: 12.834847 | BH27: 0.00025135753 | BI27: 0.00047228712 | BJ27: 17.054523 | BK27: 0.00032901727 | BL27: 0.00057942847 | BM27: 21.098379 | BN27: 0.00040442726 | BO27: 0.00049554666 | BP27: 22.856577 | BQ27: 0.00066077125 | BR27: 0.00064538235 | BS27: 29.274001 | BT27: 0.00084830984 | BU27: 0.00079279334 | BV27: 35.427695 | BW27: 0.0010293982 | BX27: 0.00047705981 | BY27: 32.966217 | BZ27: 0.00063775243 | CA27: 0.0005994875 | CB27: 40.7902 | CC27: 0.00079229431 | CD27: 0.00075975268 | CE27: 50.987749 | CF27: 0.00098991983
A28: 0.0045287228 | B28: 45.999333 | C28: 0.0012568816 | I28: 0.18460765 | J28: 181.83857 | K28: -0.038232003 | M28: 0.0030234169 | N28: 91.731736 | O28: 0.0019900796 | U28: 0 | V28: 0 | W28: 0 | AG28: 0 | AH28: 0 | AI28: 0 | AO28: 0.18027725 | AP28: 697.64877 | AQ28: -0.029873397 | AS28: 0.15498296 | AT28: 946.40822 | AU28: -0.03022565 | AW28: 0.00040406143 | AX28: 7.2403943 | AY28: 0.000282843 | AZ28: 0.00059564457 | BA28: 10.851426 | BB28: 0.00041562888 | BC28: 0.00075411434 | BD28: 13.930885 | BE28: 0.00052847989 | BF28: 0.00037403279 | BG28: 13.380982 | BH28: 0.00026182295 | BI28: 0.00049175146 | BJ28: 17.780209 | BK28: 0.00034262167 | BL28: 0.00060305762 | BM28: 21.996135 | BN28: 0.000421041 | BO28: 0.00051833192 | BP28: 23.829146 | BQ28: 0.00069026142 | BR28: 0.00067559557 | BS28: 30.519637 | BT28: 0.00088630573 | BU28: 0.0008303525 | BV28: 36.935176 | BW28: 0.0010753027 | BX28: 0.00049901974 | BY28: 34.36896 | BZ28: 0.00066632489 | CA28: 0.00062755919 | CB28: 42.52586 | CC28: 0.00082801396 | CD28: 0.00079572366 | CE28: 53.157325 | CF28: 0.0010342237
A29: 0.0080510628 | B29: 71.755355 | C29: -5.3770337e-05 | E29: 0.073003917 | F29: 84.795028 | G29: -0.023456179 | I29: 0.19567404 | J29: 184.6689 | K29: -0.038976783 | M29: 0.0060468338 | N29: 153.34542 | O29: 0.0033235684 | Q29: 0.068504997 | R29: 264.19695 | S29: -0.0099586939 | U29: 0 | V29: 4.7322225 | W29: 0.00011417507 | Y29: 0.047423178 | Z29: 483.61281 | AA29: -0.01079969 | AC29: 0.061432924 | AD29: 590.52959 | AE29: -0.01426608 | AG29: 0.0035211268 | AH29: 184.95211 | AI29: 0.0008051668 | AK29: 0.041267144 | AL29: 734.6791 | AM29: -0.0079296374 | AO29: 0.1903486 | AP29: 698.87358 | AQ29: -0.030217467 | AS29: 0.1645436 | AT29: 929.55172 | AU29: -0.030575158 | AW29: 0.0004201551 | AX29: 7.5359055 | AY29: 0.00029410857 | AZ29: 0.00061893849 | BA29: 11.294319 | BB29: 0.00043199105 | BC29: 0.00078306466 | BD29: 14.499464 | BE29: 0.00054908359 | BF29: 0.00038895737 | BG29: 13.927117 | BH29: 0.00027227016 | BI29: 0.00051116384 | BJ29: 18.505895 | BK29: 0.00035619505 | BL29: 0.00062660089 | BM29: 22.89389 | BN29: 0.00043760848 | BO29: 0.00054125876 | BP29: 24.801714 | BQ29: 0.00071983309 | BR29: 0.00070603471 | BS29: 31.765273 | BT29: 0.0009243933 | BU29: 0.000868219 | BV29: 38.442657 | BW29: 0.0011212708 | BX29: 0.00052111865 | BY29: 35.771704 | BZ29: 0.00069498734 | CA29: 0.0006558434 | CB29: 44.261521 | CC29: 0.0008638461 | CD29: 0.00083198954 | CE29: 55.326901 | CF29: 0.0010786091
A30: 0.012076594 | B30: 79.18242 | C30: -0.0016937656 | I30: 0.2027163 | J30: 185.01126 | K30: -0.039493431 | M30: 0.0070546394 | N30: 165.04066 | O30: 0.0039869283 | U30: 0.0010062298 | V30: 14.013516 | W30: -0.00028879576 | AG30: 0.0065392354 | AH30: 357.86436 | AI30: 0.0016103336 | AO30: 0.19991639 | AP30: 707.76658 | AQ30: -0.031256424 | AS30: 0.17309785 | AT30: 918.20173 | AU30: -0.03068942 | AW30: 0.00043621861 | AX30: 7.8314168 | AY30: 0.00030535303 | AZ30: 0.00064215141 | BA30: 11.737212 | BB30: 0.00044830836 | BC30: 0.00081186722 | BD30: 15.068042 | BE30: 0.00056961619 | BF30: 0.00040385601 | BG30: 14.473251 | BH30: 0.0002826992 | BI30: 0.00053052424 | BJ30: 19.23158 | BK30: 0.00036973752 | BL30: 0.00065005818 | BM30: 23.791646 | BN30: 0.00045412996 | BO30: 0.00056432753 | BP30: 25.774283 | BQ30: 0.00074948325 | BR30: 0.00073669977 | BS30: 33.010909 | BT30: 0.00096256627 | BU30: 0.00090639187 | BV30: 39.950139 | BW30: 0.001167292 | BX30: 0.00054335695 | BY30: 37.174447 | BZ30: 0.00072373704 | CA30: 0.00068434035 | CB30: 45.997182 | CC30: 0.00089978551 | CD30: 0.00086854965 | CE30: 57.496478 | CF30: 0.0011230664
